<sdf version="1.7">
  <world name="sim_world">
    <physics name="10ms" type="ode">
      <max_step_size>0.01</max_step_size>
      <real_time_factor>1.0</real_time_factor>
    </physics>
    <plugin filename="libgz-sim-physics-system.so" name="gz::sim::systems::Physics">
    </plugin>
    <plugin filename="libgz-sim-user-commands-system.so" name="gz::sim::systems::UserCommands">
    </plugin>
    <plugin filename="libgz-sim-scene-broadcaster-system.so" name="gz::sim::systems::SceneBroadcaster">
    </plugin>
    <plugin filename="libdoor.so" name="door">
    </plugin>
    <plugin filename="liblift.so" name="lift">
    </plugin>
    <scene>
      <ambient>1 1 1</ambient>
      <background>0.8 0.8 0.8</background>
      <grid>false</grid>
    </scene>
    <gui fullscreen="0">
      <window>
        <width>1000</width>
        <height>845</height>
        <style material_theme="Light" material_primary="DeepOrange" material_accent="LightBlue" toolbar_color_light="#f3f3f3" toolbar_text_color_light="#111111" toolbar_color_dark="#414141" toolbar_text_color_dark="#f3f3f3" plugin_toolbar_color_light="#bbdefb" plugin_toolbar_text_color_light="#111111" plugin_toolbar_color_dark="#607d8b" plugin_toolbar_text_color_dark="#eeeeee" />
        <menus>
          <drawer default="false">
          </drawer>
        </menus>
      </window>
      <plugin filename="MinimalScene" name="3D View">
        <gz-gui>
          <title>3D View</title>
          <property type="bool" key="showTitleBar">false</property>
          <property type="string" key="state">docked</property>
        </gz-gui>
        <engine>ogre2</engine>
        <scene>scene</scene>
        <ambient_light>0.4 0.4 0.4</ambient_light>
        <background_color>0.8 0.8 0.8</background_color>
        <camera_pose>17.481188219643688 -43.07026332036993 10 0 0.6 1.57</camera_pose>
      </plugin>
      <plugin filename="EntityContextMenuPlugin" name="Entity context menu">
        <gz-gui>
          <property key="state" type="string">floating</property>
          <property key="width" type="double">5</property>
          <property key="height" type="double">5</property>
          <property key="showTitleBar" type="bool">false</property>
        </gz-gui>
      </plugin>
      <plugin filename="GzSceneManager" name="Scene Manager">
        <gz-gui>
          <property key="resizable" type="bool">false</property>
          <property key="width" type="double">5</property>
          <property key="height" type="double">5</property>
          <property key="state" type="string">floating</property>
          <property key="showTitleBar" type="bool">false</property>
        </gz-gui>
      </plugin>
      <plugin filename="InteractiveViewControl" name="Interactive view control">
        <gz-gui>
          <property key="resizable" type="bool">false</property>
          <property key="width" type="double">5</property>
          <property key="height" type="double">5</property>
          <property key="state" type="string">floating</property>
          <property key="showTitleBar" type="bool">false</property>
        </gz-gui>
      </plugin>
      <plugin filename="CameraTracking" name="Camera Tracking">
        <gz-gui>
          <property key="resizable" type="bool">false</property>
          <property key="width" type="double">5</property>
          <property key="height" type="double">5</property>
          <property key="state" type="string">floating</property>
          <property key="showTitleBar" type="bool">false</property>
        </gz-gui>
      </plugin>
      <plugin filename="MarkerManager" name="Marker manager">
        <gz-gui>
          <property key="resizable" type="bool">false</property>
          <property key="width" type="double">5</property>
          <property key="height" type="double">5</property>
          <property key="state" type="string">floating</property>
          <property key="showTitleBar" type="bool">false</property>
        </gz-gui>
      </plugin>
      <plugin filename="SelectEntities" name="Select Entities">
        <gz-gui>
          <property key="resizable" type="bool">false</property>
          <property key="width" type="double">5</property>
          <property key="height" type="double">5</property>
          <property key="state" type="string">floating</property>
          <property key="showTitleBar" type="bool">false</property>
        </gz-gui>
      </plugin>
      <plugin filename="Spawn" name="Spawn Entities">
        <gz-gui>
          <property key="resizable" type="bool">false</property>
          <property key="width" type="double">5</property>
          <property key="height" type="double">5</property>
          <property key="state" type="string">floating</property>
          <property key="showTitleBar" type="bool">false</property>
        </gz-gui>
      </plugin>
      <plugin filename="VisualizationCapabilities" name="Visualization Capabilities">
        <gz-gui>
          <property key="resizable" type="bool">false</property>
          <property key="width" type="double">5</property>
          <property key="height" type="double">5</property>
          <property key="state" type="string">floating</property>
          <property key="showTitleBar" type="bool">false</property>
        </gz-gui>
      </plugin>
      <plugin filename="WorldControl" name="World control">
        <gz-gui>
          <title>World control</title>
          <property type="bool" key="showTitleBar">false</property>
          <property type="bool" key="resizable">false</property>
          <property type="double" key="height">72</property>
          <property type="double" key="z">1</property>
          <property type="string" key="state">floating</property>
          <anchors target="3D View">
            <line own="left" target="left" />
            <line own="bottom" target="bottom" />
          </anchors>
        </gz-gui>
        <play_pause>true</play_pause>
        <step>true</step>
        <start_paused>true</start_paused>
        <use_event>true</use_event>
      </plugin>
      <plugin filename="WorldStats" name="World stats">
        <gz-gui>
          <title>World stats</title>
          <property type="bool" key="showTitleBar">false</property>
          <property type="bool" key="resizable">false</property>
          <property type="double" key="height">110</property>
          <property type="double" key="width">290</property>
          <property type="double" key="z">1</property>
          <property type="string" key="state">floating</property>
          <anchors target="3D View">
            <line own="right" target="right" />
            <line own="bottom" target="bottom" />
          </anchors>
        </gz-gui>
        <sim_time>true</sim_time>
        <real_time>true</real_time>
        <real_time_factor>true</real_time_factor>
        <iterations>true</iterations>
      </plugin>
      <plugin filename="Shapes" name="Shapes">
        <gz-gui>
          <property key="resizable" type="bool">false</property>
          <property key="x" type="double">0</property>
          <property key="y" type="double">0</property>
          <property key="width" type="double">250</property>
          <property key="height" type="double">50</property>
          <property key="state" type="string">floating</property>
          <property key="showTitleBar" type="bool">false</property>
          <property key="cardBackground" type="string">#666666</property>
        </gz-gui>
      </plugin>
      <plugin filename="Lights" name="Lights">
        <gz-gui>
          <property key="resizable" type="bool">false</property>
          <property key="x" type="double">250</property>
          <property key="y" type="double">0</property>
          <property key="width" type="double">150</property>
          <property key="height" type="double">50</property>
          <property key="state" type="string">floating</property>
          <property key="showTitleBar" type="bool">false</property>
          <property key="cardBackground" type="string">#666666</property>
        </gz-gui>
      </plugin>
      <plugin filename="TransformControl" name="Transform control">
        <gz-gui>
          <property key="resizable" type="bool">false</property>
          <property key="x" type="double">0</property>
          <property key="y" type="double">50</property>
          <property key="width" type="double">250</property>
          <property key="height" type="double">50</property>
          <property key="state" type="string">floating</property>
          <property key="showTitleBar" type="bool">false</property>
          <property key="cardBackground" type="string">#777777</property>
        </gz-gui>
      </plugin>
      <plugin filename="Screenshot" name="Screenshot">
        <gz-gui>
          <property key="resizable" type="bool">false</property>
          <property key="x" type="double">250</property>
          <property key="y" type="double">50</property>
          <property key="width" type="double">50</property>
          <property key="height" type="double">50</property>
          <property key="state" type="string">floating</property>
          <property key="showTitleBar" type="bool">false</property>
          <property key="cardBackground" type="string">#777777</property>
        </gz-gui>
      </plugin>
      <plugin filename="CopyPaste" name="CopyPaste">
        <gz-gui>
          <property key="resizable" type="bool">false</property>
          <property key="x" type="double">300</property>
          <property key="y" type="double">50</property>
          <property key="width" type="double">100</property>
          <property key="height" type="double">50</property>
          <property key="state" type="string">floating</property>
          <property key="showTitleBar" type="bool">false</property>
          <property key="cardBackground" type="string">#777777</property>
        </gz-gui>
      </plugin>
      <plugin filename="ComponentInspector" name="Component inspector">
        <gz-gui>
          <property type="bool" key="showTitleBar">false</property>
          <property type="string" key="state">docked</property>
        </gz-gui>
      </plugin>
      <plugin filename="EntityTree" name="Entity tree">
        <gz-gui>
          <property type="bool" key="showTitleBar">false</property>
          <property type="string" key="state">docked</property>
        </gz-gui>
      </plugin>
      <plugin filename="toggle_charging" name="toggle_charging" />
      <plugin name="toggle_floors" filename="toggle_floors">
        <floor name="L1" model_name="roomB_def_L1">
          <model name="OpenRobotics/AdjTable" />
          <model name="OpenRobotics/AdjTable_2" />
          <model name="OpenRobotics/AdjTable_3" />
          <model name="OpenRobotics/AdjTable_4" />
          <model name="OpenRobotics/AdjTable_5" />
          <model name="OpenRobotics/AdjTable_6" />
          <model name="OpenRobotics/AdjTable_7" />
          <model name="OpenRobotics/AdjTable_8" />
          <model name="OpenRobotics/AdjTable_9" />
          <model name="OpenRobotics/AdjTable_10" />
          <model name="OpenRobotics/AdjTable_11" />
          <model name="OpenRobotics/AdjTable_12" />
          <model name="OpenRobotics/AdjTable_13" />
          <model name="OpenRobotics/AdjTable_14" />
          <model name="OpenRobotics/AdjTable_15" />
          <model name="OpenRobotics/AdjTable_16" />
          <model name="OpenRobotics/AdjTable_17" />
          <model name="OpenRobotics/AdjTable_18" />
          <model name="OpenRobotics/AdjTable_19" />
          <model name="OpenRobotics/AdjTable_20" />
          <model name="OpenRobotics/AdjTable_21" />
          <model name="OpenRobotics/AdjTable_22" />
          <model name="OpenRobotics/AdjTable_23" />
          <model name="OpenRobotics/AdjTable_24" />
          <model name="OpenRobotics/AdjTable_25" />
          <model name="OpenRobotics/AdjTable_26" />
          <model name="OpenRobotics/AdjTable_27" />
          <model name="OpenRobotics/AdjTable_28" />
          <model name="OpenRobotics/AdjTable_29" />
          <model name="OpenRobotics/AdjTable_30" />
          <model name="OpenRobotics/AdjTable_31" />
          <model name="OpenRobotics/AdjTable_32" />
          <model name="OpenRobotics/AdjTable_33" />
          <model name="OpenRobotics/AdjTable_34" />
          <model name="OpenRobotics/AdjTable_35" />
          <model name="OpenRobotics/AdjTable_36" />
          <model name="OpenRobotics/AdjTable_37" />
          <model name="OpenRobotics/AdjTable_38" />
          <model name="OpenRobotics/AdjTable_39" />
          <model name="OpenRobotics/AdjTable_40" />
          <model name="OpenRobotics/AdjTable_41" />
          <model name="OpenRobotics/AdjTable_42" />
          <model name="OpenRobotics/AdjTable_43" />
          <model name="OpenRobotics/AdjTable_44" />
          <model name="OpenRobotics/AdjTable_45" />
          <model name="OpenRobotics/AdjTable_46" />
          <model name="OpenRobotics/AdjTable_47" />
          <model name="OpenRobotics/AdjTable_48" />
          <model name="OpenRobotics/AdjTable_49" />
          <model name="OpenRobotics/AdjTable_50" />
          <model name="OpenRobotics/AdjTable_51" />
          <model name="OpenRobotics/AdjTable_52" />
          <model name="OpenRobotics/AdjTable_53" />
          <model name="OpenRobotics/AdjTable_54" />
          <model name="OpenRobotics/AdjTable_55" />
          <model name="OpenRobotics/AdjTable_56" />
          <model name="OpenRobotics/AdjTable_57" />
          <model name="OpenRobotics/AdjTable_58" />
          <model name="OpenRobotics/AdjTable_59" />
          <model name="OpenRobotics/AdjTable_60" />
          <model name="OpenRobotics/AdjTable_61" />
          <model name="OpenRobotics/AdjTable_62" />
          <model name="OpenRobotics/AdjTable_63" />
          <model name="OpenRobotics/AdjTable_64" />
          <model name="OpenRobotics/Chair" />
          <model name="OpenRobotics/Chair_2" />
          <model name="OpenRobotics/Chair_3" />
          <model name="OpenRobotics/Chair_4" />
          <model name="OpenRobotics/Chair_5" />
          <model name="OpenRobotics/Chair_6" />
          <model name="OpenRobotics/Chair_7" />
          <model name="OpenRobotics/Chair_8" />
          <model name="OpenRobotics/Chair_9" />
          <model name="OpenRobotics/Chair_10" />
          <model name="OpenRobotics/Chair_11" />
          <model name="OpenRobotics/Chair_12" />
          <model name="OpenRobotics/Chair_13" />
          <model name="OpenRobotics/Chair_14" />
          <model name="OpenRobotics/Chair_15" />
          <model name="OpenRobotics/Chair_16" />
          <model name="OpenRobotics/Chair_17" />
          <model name="OpenRobotics/Chair_18" />
          <model name="OpenRobotics/Chair_19" />
          <model name="OpenRobotics/Chair_20" />
          <model name="OpenRobotics/Chair_21" />
          <model name="OpenRobotics/Chair_22" />
          <model name="OpenRobotics/Chair_23" />
          <model name="OpenRobotics/Chair_24" />
          <model name="OpenRobotics/Chair_25" />
          <model name="OpenRobotics/Chair_26" />
          <model name="OpenRobotics/Chair_27" />
          <model name="OpenRobotics/Chair_28" />
          <model name="OpenRobotics/Chair_29" />
          <model name="OpenRobotics/Chair_30" />
          <model name="OpenRobotics/Chair_31" />
          <model name="OpenRobotics/Chair_32" />
          <model name="OpenRobotics/Chair_33" />
          <model name="OpenRobotics/Chair_34" />
          <model name="OpenRobotics/Chair_35" />
          <model name="OpenRobotics/Chair_36" />
          <model name="OpenRobotics/Chair_37" />
          <model name="OpenRobotics/Chair_38" />
          <model name="OpenRobotics/Chair_39" />
          <model name="OpenRobotics/Chair_40" />
          <model name="OpenRobotics/Chair_41" />
          <model name="OpenRobotics/Chair_42" />
          <model name="OpenRobotics/Chair_43" />
          <model name="OpenRobotics/Chair_44" />
          <model name="OpenRobotics/Chair_45" />
          <model name="OpenRobotics/Chair_46" />
          <model name="OpenRobotics/Chair_47" />
          <model name="OpenRobotics/Chair_48" />
          <model name="OpenRobotics/Chair_49" />
          <model name="OpenRobotics/Chair_50" />
          <model name="OpenRobotics/Chair_51" />
          <model name="OpenRobotics/Chair_52" />
          <model name="OpenRobotics/Chair_53" />
          <model name="OpenRobotics/Chair_54" />
          <model name="OpenRobotics/Chair_55" />
          <model name="OpenRobotics/Chair_56" />
          <model name="OpenRobotics/Chair_57" />
          <model name="OpenRobotics/Chair_58" />
          <model name="OpenRobotics/Chair_59" />
          <model name="OpenRobotics/Chair_60" />
          <model name="OpenRobotics/Chair_61" />
          <model name="OpenRobotics/Chair_62" />
          <model name="OpenRobotics/Chair_63" />
          <model name="OpenRobotics/Chair_64" />
          <model name="OpenRobotics/Chair_65" />
          <model name="OpenRobotics/Chair_66" />
          <model name="OpenRobotics/Chair_67" />
          <model name="OpenRobotics/Chair_68" />
          <model name="OpenRobotics/Chair_69" />
          <model name="OpenRobotics/Chair_70" />
          <model name="OpenRobotics/Chair_71" />
          <model name="OpenRobotics/Chair_72" />
          <model name="OpenRobotics/Chair_73" />
          <model name="OpenRobotics/Chair_74" />
          <model name="OpenRobotics/Chair_75" />
          <model name="OpenRobotics/Chair_76" />
          <model name="OpenRobotics/Chair_77" />
          <model name="OpenRobotics/Chair_78" />
          <model name="OpenRobotics/Chair_79" />
          <model name="OpenRobotics/Chair_80" />
          <model name="OpenRobotics/Chair_81" />
          <model name="OpenRobotics/Chair_82" />
          <model name="OpenRobotics/Chair_83" />
          <model name="OpenRobotics/Chair_84" />
          <model name="OpenRobotics/Chair_85" />
          <model name="OpenRobotics/Chair_86" />
          <model name="OpenRobotics/Chair_87" />
          <model name="OpenRobotics/Chair_88" />
          <model name="OpenRobotics/Chair_89" />
          <model name="OpenRobotics/Chair_90" />
          <model name="OpenRobotics/Chair_91" />
          <model name="OpenRobotics/Chair_92" />
          <model name="OpenRobotics/Chair_93" />
          <model name="OpenRobotics/Chair_94" />
          <model name="OpenRobotics/Chair_95" />
          <model name="OpenRobotics/Chair_96" />
          <model name="OpenRobotics/Chair_97" />
          <model name="OpenRobotics/Chair_98" />
          <model name="OpenRobotics/Chair_99" />
          <model name="OpenRobotics/Chair_100" />
          <model name="OpenRobotics/Chair_101" />
          <model name="OpenRobotics/Chair_102" />
          <model name="OpenRobotics/Chair_103" />
          <model name="OpenRobotics/Chair_104" />
          <model name="OpenRobotics/Chair_105" />
          <model name="OpenRobotics/Chair_106" />
          <model name="OpenRobotics/Chair_107" />
          <model name="OpenRobotics/Chair_108" />
          <model name="OpenRobotics/Chair_109" />
          <model name="OpenRobotics/Chair_110" />
          <model name="OpenRobotics/Chair_111" />
          <model name="OpenRobotics/Chair_112" />
          <model name="OpenRobotics/Chair_113" />
          <model name="OpenRobotics/Chair_114" />
          <model name="OpenRobotics/Chair_115" />
          <model name="OpenRobotics/Chair_116" />
          <model name="OpenRobotics/Chair_117" />
          <model name="OpenRobotics/Chair_118" />
          <model name="OpenRobotics/Chair_119" />
          <model name="OpenRobotics/Chair_120" />
          <model name="OpenRobotics/Chair_121" />
          <model name="OpenRobotics/Chair_122" />
          <model name="OpenRobotics/Chair_123" />
          <model name="OpenRobotics/Chair_124" />
          <model name="OpenRobotics/Chair_125" />
          <model name="OpenRobotics/Chair_126" />
          <model name="OpenRobotics/Chair_127" />
          <model name="OpenRobotics/Chair_128" />
          <model name="OpenRobotics/Chair_129" />
          <model name="OpenRobotics/Chair_130" />
          <model name="OpenRobotics/Chair_131" />
          <model name="OpenRobotics/Chair_132" />
          <model name="OpenRobotics/Chair_133" />
          <model name="OpenRobotics/Chair_134" />
          <model name="OpenRobotics/Chair_135" />
          <model name="OpenRobotics/Chair_136" />
          <model name="OpenRobotics/Chair_137" />
          <model name="OpenRobotics/Chair_138" />
          <model name="door1" />
          <model name="door2" />
          <model name="door3" />
          <model name="door4" />
          <model name="ShaftDoor_lift_L1_doors" />
        </floor>
        <floor name="L2" model_name="roomB_def_L2">
          <model name="OpenRobotics/AdjTable_65" />
          <model name="OpenRobotics/AdjTable_66" />
          <model name="OpenRobotics/AdjTable_67" />
          <model name="OpenRobotics/AdjTable_68" />
          <model name="OpenRobotics/AdjTable_69" />
          <model name="OpenRobotics/AdjTable_70" />
          <model name="OpenRobotics/AdjTable_71" />
          <model name="OpenRobotics/AdjTable_72" />
          <model name="OpenRobotics/AdjTable_73" />
          <model name="OpenRobotics/AdjTable_74" />
          <model name="OpenRobotics/AdjTable_75" />
          <model name="OpenRobotics/AdjTable_76" />
          <model name="OpenRobotics/Chair_139" />
          <model name="OpenRobotics/Chair_140" />
          <model name="OpenRobotics/Chair_141" />
          <model name="OpenRobotics/Chair_142" />
          <model name="OpenRobotics/Chair_143" />
          <model name="OpenRobotics/Chair_144" />
          <model name="OpenRobotics/Chair_145" />
          <model name="OpenRobotics/Chair_146" />
          <model name="OpenRobotics/Chair_147" />
          <model name="OpenRobotics/Chair_148" />
          <model name="OpenRobotics/Chair_149" />
          <model name="OpenRobotics/Chair_150" />
          <model name="OpenRobotics/Chair_151" />
          <model name="OpenRobotics/Chair_152" />
          <model name="OpenRobotics/Chair_153" />
          <model name="OpenRobotics/Chair_154" />
          <model name="OpenRobotics/Chair_155" />
          <model name="OpenRobotics/Chair_156" />
          <model name="OpenRobotics/Chair_157" />
          <model name="OpenRobotics/Chair_158" />
          <model name="OpenRobotics/Chair_159" />
          <model name="OpenRobotics/Chair_160" />
          <model name="OpenRobotics/Chair_161" />
          <model name="OpenRobotics/Chair_162" />
          <model name="OpenRobotics/Chair_163" />
          <model name="OpenRobotics/Chair_164" />
          <model name="OpenRobotics/Chair_165" />
          <model name="OpenRobotics/AdjTable_77" />
          <model name="door6" />
          <model name="door7" />
          <model name="door5" />
          <model name="ShaftDoor_lift_L2_doors" />
        </floor>
      </plugin>
    </gui>
    <light type="directional" name="sun">
      <cast_shadows>true</cast_shadows>
      <pose>0 0 10 0 0 0</pose>
      <diffuse>1 1 1 1</diffuse>
      <specular>0.2 0.2 0.2 1</specular>
      <attenuation>
        <range>1000</range>
        <constant>0.09</constant>
        <linear>0.001</linear>
        <quadratic>0.001</quadratic>
      </attenuation>
      <direction>-0.5 0.1 -0.9</direction>
    </light>
    <include>
      <name>OpenRobotics/AdjTable</name>
      <uri>model://AdjTable</uri>
      <pose>15.750262556569005 -11.221788694473265 0.0 0 0 0.0</pose>
      <static>True</static>
    </include>
    <include>
      <name>OpenRobotics/AdjTable_2</name>
      <uri>model://AdjTable</uri>
      <pose>17.307932709138242 -11.221788694473265 0.0 0 0 0.0</pose>
      <static>True</static>
    </include>
    <include>
      <name>OpenRobotics/AdjTable_3</name>
      <uri>model://AdjTable</uri>
      <pose>19.557886562832174 -11.20017312821035 0.0 0 0 0.0</pose>
      <static>True</static>
    </include>
    <include>
      <name>OpenRobotics/AdjTable_4</name>
      <uri>model://AdjTable</uri>
      <pose>21.13630664061257 -11.209516959563105 0.0 0 0 0.0</pose>
      <static>True</static>
    </include>
    <include>
      <name>OpenRobotics/AdjTable_5</name>
      <uri>model://AdjTable</uri>
      <pose>23.47585434316303 -11.238032194209117 0.0 0 0 0.0</pose>
      <static>True</static>
    </include>
    <include>
      <name>OpenRobotics/AdjTable_6</name>
      <uri>model://AdjTable</uri>
      <pose>24.988001960422384 -11.238032194209117 0.0 0 0 0.0</pose>
      <static>True</static>
    </include>
    <include>
      <name>OpenRobotics/AdjTable_7</name>
      <uri>model://AdjTable</uri>
      <pose>15.880083254301153 -12.7794588470425 0.0 0 0 0.0</pose>
      <static>True</static>
    </include>
    <include>
      <name>OpenRobotics/AdjTable_8</name>
      <uri>model://AdjTable</uri>
      <pose>17.394471354282697 -12.7794588470425 0.0 0 0 0.0</pose>
      <static>True</static>
    </include>
    <include>
      <name>OpenRobotics/AdjTable_9</name>
      <uri>model://AdjTable</uri>
      <pose>19.622784181682782 -12.7794588470425 0.0 0 0 0.0</pose>
      <static>True</static>
    </include>
    <include>
      <name>OpenRobotics/AdjTable_10</name>
      <uri>model://AdjTable</uri>
      <pose>21.137172281664323 -12.7794588470425 0.0 0 0 0.0</pose>
      <static>True</static>
    </include>
    <include>
      <name>OpenRobotics/AdjTable_11</name>
      <uri>model://AdjTable</uri>
      <pose>23.365510569095342 -12.757817820748652 0.0 0 0 0.0</pose>
      <static>True</static>
    </include>
    <include>
      <name>OpenRobotics/AdjTable_12</name>
      <uri>model://AdjTable</uri>
      <pose>24.923155261633642 -12.73620225448574 0.0 0 0 0.0</pose>
      <static>True</static>
    </include>
    <include>
      <name>OpenRobotics/AdjTable_13</name>
      <uri>model://AdjTable</uri>
      <pose>15.858442228007307 -14.164051709322829 0.0 0 0 0.0</pose>
      <static>True</static>
    </include>
    <include>
      <name>OpenRobotics/AdjTable_14</name>
      <uri>model://AdjTable</uri>
      <pose>17.372830327988847 -14.164051709322829 0.0 0 0 0.0</pose>
      <static>True</static>
    </include>
    <include>
      <name>OpenRobotics/AdjTable_15</name>
      <uri>model://AdjTable</uri>
      <pose>19.624159023353215 -14.148215570081916 0.0 0 0 0.0</pose>
      <static>True</static>
    </include>
    <include>
      <name>OpenRobotics/AdjTable_16</name>
      <uri>model://AdjTable</uri>
      <pose>21.15881330795817 -14.14241068302898 0.0 0 0 0.0</pose>
      <static>True</static>
    </include>
    <include>
      <name>OpenRobotics/AdjTable_17</name>
      <uri>model://AdjTable</uri>
      <pose>23.495305806796555 -14.14241068302898 0.0 0 0 0.0</pose>
      <static>True</static>
    </include>
    <include>
      <name>OpenRobotics/AdjTable_18</name>
      <uri>model://AdjTable</uri>
      <pose>24.944796287927492 -14.14241068302898 0.0 0 0 0.0</pose>
      <static>True</static>
    </include>
    <include>
      <name>OpenRobotics/AdjTable_19</name>
      <uri>model://AdjTable</uri>
      <pose>15.815185635450549 -15.527003545309306 0.0 0 0 0.0</pose>
      <static>True</static>
    </include>
    <include>
      <name>OpenRobotics/AdjTable_20</name>
      <uri>model://AdjTable</uri>
      <pose>17.398748639479596 -15.546225868664433 0.0 0 0 0.0</pose>
      <static>True</static>
    </include>
    <include>
      <name>OpenRobotics/AdjTable_21</name>
      <uri>model://AdjTable</uri>
      <pose>19.652699718030156 -15.574766563341376 0.0 0 0 0.0</pose>
      <static>True</static>
    </include>
    <include>
      <name>OpenRobotics/AdjTable_22</name>
      <uri>model://AdjTable</uri>
      <pose>21.13630664061257 -15.574766563341376 0.0 0 0 0.0</pose>
      <static>True</static>
    </include>
    <include>
      <name>OpenRobotics/AdjTable_23</name>
      <uri>model://AdjTable</uri>
      <pose>23.32222851650765 -15.591901164159916 0.0 0 0 0.0</pose>
      <static>True</static>
    </include>
    <include>
      <name>OpenRobotics/AdjTable_24</name>
      <uri>model://AdjTable</uri>
      <pose>24.923155261633642 -15.591901164159916 0.0 0 0 0.0</pose>
      <static>True</static>
    </include>
    <include>
      <name>OpenRobotics/AdjTable_25</name>
      <uri>model://AdjTable</uri>
      <pose>15.83680120171346 -16.846673328708096 0.0 0 0 0.0</pose>
      <static>True</static>
    </include>
    <include>
      <name>OpenRobotics/AdjTable_26</name>
      <uri>model://AdjTable</uri>
      <pose>17.416112380576543 -16.846673328708096 0.0 0 0 0.0</pose>
      <static>True</static>
    </include>
    <include>
      <name>OpenRobotics/AdjTable_27</name>
      <uri>model://AdjTable</uri>
      <pose>19.652699718030156 -16.88718023792399 0.0 0 0 0.0</pose>
      <static>True</static>
    </include>
    <include>
      <name>OpenRobotics/AdjTable_28</name>
      <uri>model://AdjTable</uri>
      <pose>21.13630664061257 -16.88718023792399 0.0 0 0 0.0</pose>
      <static>True</static>
    </include>
    <include>
      <name>OpenRobotics/AdjTable_29</name>
      <uri>model://AdjTable</uri>
      <pose>23.365510569095342 -16.911596407589634 0.0 0 0 0.0</pose>
      <static>True</static>
    </include>
    <include>
      <name>OpenRobotics/AdjTable_30</name>
      <uri>model://AdjTable</uri>
      <pose>24.923155261633642 -16.911596407589634 0.0 0 0 0.0</pose>
      <static>True</static>
    </include>
    <include>
      <name>OpenRobotics/AdjTable_31</name>
      <uri>model://AdjTable</uri>
      <pose>15.880083254301153 -18.29616380983903 0.0 0 0 0.0</pose>
      <static>True</static>
    </include>
    <include>
      <name>OpenRobotics/AdjTable_32</name>
      <uri>model://AdjTable</uri>
      <pose>17.394471354282697 -18.29616380983903 0.0 0 0 0.0</pose>
      <static>True</static>
    </include>
    <include>
      <name>OpenRobotics/AdjTable_33</name>
      <uri>model://AdjTable</uri>
      <pose>19.622784181682782 -18.274548243576117 0.0 0 0 0.0</pose>
      <static>True</static>
    </include>
    <include>
      <name>OpenRobotics/AdjTable_34</name>
      <uri>model://AdjTable</uri>
      <pose>21.11555671540141 -18.274548243576117 0.0 0 0 0.0</pose>
      <static>True</static>
    </include>
    <include>
      <name>OpenRobotics/AdjTable_35</name>
      <uri>model://AdjTable</uri>
      <pose>23.452049214239793 -18.317804836132876 0.0 0 0 0.0</pose>
      <static>True</static>
    </include>
    <include>
      <name>OpenRobotics/AdjTable_36</name>
      <uri>model://AdjTable</uri>
      <pose>24.944796287927492 -18.317804836132876 0.0 0 0 0.0</pose>
      <static>True</static>
    </include>
    <include>
      <name>OpenRobotics/AdjTable_37</name>
      <uri>model://AdjTable</uri>
      <pose>15.901698820564068 -19.637500079562596 0.0 0 0 0.0</pose>
      <static>True</static>
    </include>
    <include>
      <name>OpenRobotics/AdjTable_38</name>
      <uri>model://AdjTable</uri>
      <pose>17.416112380576543 -19.65911564582551 0.0 0 0 0.0</pose>
      <static>True</static>
    </include>
    <include>
      <name>OpenRobotics/AdjTable_39</name>
      <uri>model://AdjTable</uri>
      <pose>19.601143155388936 -19.65911564582551 0.0 0 0 0.0</pose>
      <static>True</static>
    </include>
    <include>
      <name>OpenRobotics/AdjTable_40</name>
      <uri>model://AdjTable</uri>
      <pose>21.15881330795817 -19.637500079562596 0.0 0 0 0.0</pose>
      <static>True</static>
    </include>
    <include>
      <name>OpenRobotics/AdjTable_41</name>
      <uri>model://AdjTable</uri>
      <pose>23.452049214239793 -19.702397698413204 0.0 0 0 0.0</pose>
      <static>True</static>
    </include>
    <include>
      <name>OpenRobotics/AdjTable_42</name>
      <uri>model://AdjTable</uri>
      <pose>25.031334933071946 -19.702397698413204 0.0 0 0 0.0</pose>
      <static>True</static>
    </include>
    <include>
      <name>OpenRobotics/AdjTable_43</name>
      <uri>model://AdjTable</uri>
      <pose>15.880083254301153 -21.043708508105837 0.0 0 0 0.0</pose>
      <static>True</static>
    </include>
    <include>
      <name>OpenRobotics/AdjTable_44</name>
      <uri>model://AdjTable</uri>
      <pose>17.416112380576543 -21.043708508105837 0.0 0 0 0.0</pose>
      <static>True</static>
    </include>
    <include>
      <name>OpenRobotics/AdjTable_45</name>
      <uri>model://AdjTable</uri>
      <pose>19.687681800533387 -21.086990560693533 0.0 0 0 0.0</pose>
      <static>True</static>
    </include>
    <include>
      <name>OpenRobotics/AdjTable_46</name>
      <uri>model://AdjTable</uri>
      <pose>21.24535195310262 -21.086990560693533 0.0 0 0 0.0</pose>
      <static>True</static>
    </include>
    <include>
      <name>OpenRobotics/AdjTable_47</name>
      <uri>model://AdjTable</uri>
      <pose>23.452049214239793 -21.13024715325029 0.0 0 0 0.0</pose>
      <static>True</static>
    </include>
    <include>
      <name>OpenRobotics/AdjTable_48</name>
      <uri>model://AdjTable</uri>
      <pose>25.031334933071946 -21.151888179544137 0.0 0 0 0.0</pose>
      <static>True</static>
    </include>
    <include>
      <name>OpenRobotics/AdjTable_49</name>
      <uri>model://AdjTable</uri>
      <pose>15.83680120171346 -22.449942396680015 0.0 0 0 0.0</pose>
      <static>True</static>
    </include>
    <include>
      <name>OpenRobotics/AdjTable_50</name>
      <uri>model://AdjTable</uri>
      <pose>17.394471354282697 -22.471557962942924 0.0 0 0 0.0</pose>
      <static>True</static>
    </include>
    <include>
      <name>OpenRobotics/AdjTable_51</name>
      <uri>model://AdjTable</uri>
      <pose>19.687681800533387 -22.428301370386166 0.0 0 0 0.0</pose>
      <static>True</static>
    </include>
    <include>
      <name>OpenRobotics/AdjTable_52</name>
      <uri>model://AdjTable</uri>
      <pose>21.180454334252016 -22.40666034409232 0.0 0 0 0.0</pose>
      <static>True</static>
    </include>
    <include>
      <name>OpenRobotics/AdjTable_53</name>
      <uri>model://AdjTable</uri>
      <pose>23.43040818794595 -22.40666034409232 0.0 0 0 0.0</pose>
      <static>True</static>
    </include>
    <include>
      <name>OpenRobotics/AdjTable_54</name>
      <uri>model://AdjTable</uri>
      <pose>24.944796287927492 -22.449942396680015 0.0 0 0 0.0</pose>
      <static>True</static>
    </include>
    <include>
      <name>OpenRobotics/AdjTable_55</name>
      <uri>model://AdjTable</uri>
      <pose>15.901698820564068 -23.856150825223253 0.0 0 0 0.0</pose>
      <static>True</static>
    </include>
    <include>
      <name>OpenRobotics/AdjTable_56</name>
      <uri>model://AdjTable</uri>
      <pose>17.394471354282697 -23.856150825223253 0.0 0 0 0.0021</pose>
      <static>True</static>
    </include>
    <include>
      <name>OpenRobotics/AdjTable_57</name>
      <uri>model://AdjTable</uri>
      <pose>19.666066234270474 -23.856150825223253 0.0 0 0 0.0</pose>
      <static>True</static>
    </include>
    <include>
      <name>OpenRobotics/AdjTable_58</name>
      <uri>model://AdjTable</uri>
      <pose>21.20209536054586 -23.83453525896034 0.0 0 0 0.0</pose>
      <static>True</static>
    </include>
    <include>
      <name>OpenRobotics/AdjTable_59</name>
      <uri>model://AdjTable</uri>
      <pose>23.452049214239793 -23.856150825223253 0.0 0 0 0.0</pose>
      <static>True</static>
    </include>
    <include>
      <name>OpenRobotics/AdjTable_60</name>
      <uri>model://AdjTable</uri>
      <pose>24.98805288048425 -23.877791851517102 0.0 0 0 0.0</pose>
      <static>True</static>
    </include>
    <include>
      <name>OpenRobotics/AdjTable_61</name>
      <uri>model://AdjTable</uri>
      <pose>18.71587241978499 -38.9972821416978 0.0 0 0 0.0</pose>
      <static>True</static>
    </include>
    <include>
      <name>OpenRobotics/AdjTable_62</name>
      <uri>model://AdjTable</uri>
      <pose>30.161785766569707 -40.94186838437009 0.0 0 0 1.5708</pose>
      <static>True</static>
    </include>
    <include>
      <name>OpenRobotics/AdjTable_63</name>
      <uri>model://AdjTable</uri>
      <pose>30.186405616482823 -42.93566886683767 0.0 0 0 1.5708</pose>
      <static>True</static>
    </include>
    <include>
      <name>OpenRobotics/AdjTable_64</name>
      <uri>model://AdjTable</uri>
      <pose>14.671801106238345 -32.88081523019051 0.0 0 0 0.012</pose>
      <static>True</static>
    </include>
    <include>
      <name>OpenRobotics/Chair</name>
      <uri>model://Chair</uri>
      <pose>14.133525132233036 -33.80358859136014 0.0 0 0 1.5708</pose>
      <static>True</static>
    </include>
    <include>
      <name>OpenRobotics/Chair_2</name>
      <uri>model://Chair</uri>
      <pose>14.70255682360654 -33.78818527264511 0.0 0 0 1.5708</pose>
      <static>True</static>
    </include>
    <include>
      <name>OpenRobotics/Chair_3</name>
      <uri>model://Chair</uri>
      <pose>15.286966373664143 -33.80358859136014 0.0 0 0 1.5708</pose>
      <static>True</static>
    </include>
    <include>
      <name>OpenRobotics/Chair_4</name>
      <uri>model://Chair</uri>
      <pose>28.907573722702075 -40.351450267012076 0.0 0 0 0.0</pose>
      <static>True</static>
    </include>
    <include>
      <name>OpenRobotics/Chair_5</name>
      <uri>model://Chair</uri>
      <pose>28.872184279703898 -40.95314717807382 0.0 0 0 0.0</pose>
      <static>True</static>
    </include>
    <include>
      <name>OpenRobotics/Chair_6</name>
      <uri>model://Chair</uri>
      <pose>28.907573722702075 -41.48403974310828 0.0 0 0 0.0</pose>
      <static>True</static>
    </include>
    <include>
      <name>OpenRobotics/Chair_7</name>
      <uri>model://Chair</uri>
      <pose>28.907573722702075 -42.29809877219001 0.0 0 0 0.0</pose>
      <static>True</static>
    </include>
    <include>
      <name>OpenRobotics/Chair_8</name>
      <uri>model://Chair</uri>
      <pose>28.942963165700245 -42.829016797255406 0.0 0 0 0.0</pose>
      <static>True</static>
    </include>
    <include>
      <name>OpenRobotics/Chair_9</name>
      <uri>model://Chair</uri>
      <pose>28.907573722702075 -43.43071370831716 0.0 0 0 0.0</pose>
      <static>True</static>
    </include>
    <include>
      <name>OpenRobotics/Chair_10</name>
      <uri>model://Chair</uri>
      <pose>31.455944598972685 -43.572271480309844 0.0 0 0 -3.1416</pose>
      <static>True</static>
    </include>
    <include>
      <name>OpenRobotics/Chair_11</name>
      <uri>model://Chair</uri>
      <pose>31.420529695943582 -42.793601894226306 0.0 0 0 -3.1416</pose>
      <static>True</static>
    </include>
    <include>
      <name>OpenRobotics/Chair_12</name>
      <uri>model://Chair</uri>
      <pose>31.420529695943582 -42.05034721117186 0.0 0 0 3.1416</pose>
      <static>True</static>
    </include>
    <include>
      <name>OpenRobotics/Chair_13</name>
      <uri>model://Chair</uri>
      <pose>31.420529695943582 -41.165509296093795 0.0 0 0 -3.1416</pose>
      <static>True</static>
    </include>
    <include>
      <name>OpenRobotics/Chair_14</name>
      <uri>model://Chair</uri>
      <pose>31.455944598972685 -40.528397482002944 0.0 0 0 -3.1416</pose>
      <static>True</static>
    </include>
    <include>
      <name>OpenRobotics/Chair_15</name>
      <uri>model://Chair</uri>
      <pose>31.420529695943582 -39.785142798948506 0.0 0 0 -3.1416</pose>
      <static>True</static>
    </include>
    <include>
      <name>OpenRobotics/Chair_16</name>
      <uri>model://Chair</uri>
      <pose>18.28944236167247 -39.678949009923045 0.0 0 0 1.5708</pose>
      <static>True</static>
    </include>
    <include>
      <name>OpenRobotics/Chair_17</name>
      <uri>model://Chair</uri>
      <pose>19.174280276750537 -39.678949009923045 0.0 0 0 1.5708</pose>
      <static>True</static>
    </include>
    <include>
      <name>OpenRobotics/Chair_18</name>
      <uri>model://Chair</uri>
      <pose>15.555620620079052 -11.928788293477776 0.0 0 0 1.5708</pose>
      <static>True</static>
    </include>
    <include>
      <name>OpenRobotics/Chair_19</name>
      <uri>model://Chair</uri>
      <pose>16.21254033823651 -11.906154325977507 0.0 0 0 1.5708</pose>
      <static>True</static>
    </include>
    <include>
      <name>OpenRobotics/Chair_20</name>
      <uri>model://Chair</uri>
      <pose>17.005340241488394 -11.928788293477776 0.0 0 0 1.5708</pose>
      <static>True</static>
    </include>
    <include>
      <name>OpenRobotics/Chair_21</name>
      <uri>model://Chair</uri>
      <pose>17.66225995964585 -11.906154325977507 0.0 0 0 1.5708</pose>
      <static>True</static>
    </include>
    <include>
      <name>OpenRobotics/Chair_22</name>
      <uri>model://Chair</uri>
      <pose>19.406475758868044 -11.951447721008982 0.0 0 0 1.5708</pose>
      <static>True</static>
    </include>
    <include>
      <name>OpenRobotics/Chair_23</name>
      <uri>model://Chair</uri>
      <pose>20.018076621963097 -11.928788293477776 0.0 0 0 1.5708</pose>
      <static>True</static>
    </include>
    <include>
      <name>OpenRobotics/Chair_24</name>
      <uri>model://Chair</uri>
      <pose>20.856195380277388 -11.928788293477776 0.0 0 0 1.5708</pose>
      <static>True</static>
    </include>
    <include>
      <name>OpenRobotics/Chair_25</name>
      <uri>model://Chair</uri>
      <pose>21.535749065935114 -11.906154325977507 0.0 0 0 1.5708</pose>
      <static>True</static>
    </include>
    <include>
      <name>OpenRobotics/Chair_26</name>
      <uri>model://Chair</uri>
      <pose>23.189352615063427 -11.951447721008982 0.0 0 0 1.5708</pose>
      <static>True</static>
    </include>
    <include>
      <name>OpenRobotics/Chair_27</name>
      <uri>model://Chair</uri>
      <pose>23.800953478158476 -11.951447721008982 0.0 0 0 1.5708</pose>
      <static>True</static>
    </include>
    <include>
      <name>OpenRobotics/Chair_28</name>
      <uri>model://Chair</uri>
      <pose>24.6390976965037 -11.951447721008982 0.0 0 0 1.5708</pose>
      <static>True</static>
    </include>
    <include>
      <name>OpenRobotics/Chair_29</name>
      <uri>model://Chair</uri>
      <pose>25.31865138216143 -11.928788293477776 0.0 0 0 1.5708</pose>
      <static>True</static>
    </include>
    <include>
      <name>OpenRobotics/Chair_30</name>
      <uri>model://Chair</uri>
      <pose>15.578280047610257 -13.423826769949525 0.0 0 0 1.5708</pose>
      <static>True</static>
    </include>
    <include>
      <name>OpenRobotics/Chair_31</name>
      <uri>model://Chair</uri>
      <pose>16.21254033823651 -13.40116734241832 0.0 0 0 1.5708</pose>
      <static>True</static>
    </include>
    <include>
      <name>OpenRobotics/Chair_32</name>
      <uri>model://Chair</uri>
      <pose>17.005340241488394 -13.40116734241832 0.0 0 0 1.5708</pose>
      <static>True</static>
    </include>
    <include>
      <name>OpenRobotics/Chair_33</name>
      <uri>model://Chair</uri>
      <pose>17.66225995964585 -13.40116734241832 0.0 0 0 1.5708</pose>
      <static>True</static>
    </include>
    <include>
      <name>OpenRobotics/Chair_34</name>
      <uri>model://Chair</uri>
      <pose>19.406475758868044 -13.40116734241832 0.0 0 0 1.5708</pose>
      <static>True</static>
    </include>
    <include>
      <name>OpenRobotics/Chair_35</name>
      <uri>model://Chair</uri>
      <pose>20.018076621963097 -13.40116734241832 0.0 0 0 1.5708</pose>
      <static>True</static>
    </include>
    <include>
      <name>OpenRobotics/Chair_36</name>
      <uri>model://Chair</uri>
      <pose>20.87885480780859 -13.37853337491805 0.0 0 0 1.5708</pose>
      <static>True</static>
    </include>
    <include>
      <name>OpenRobotics/Chair_37</name>
      <uri>model://Chair</uri>
      <pose>21.535749065935114 -13.37853337491805 0.0 0 0 1.5708</pose>
      <static>True</static>
    </include>
    <include>
      <name>OpenRobotics/Chair_38</name>
      <uri>model://Chair</uri>
      <pose>23.16669318753222 -13.37853337491805 0.0 0 0 1.5708</pose>
      <static>True</static>
    </include>
    <include>
      <name>OpenRobotics/Chair_39</name>
      <uri>model://Chair</uri>
      <pose>23.800953478158476 -13.37853337491805 0.0 0 0 1.5708</pose>
      <static>True</static>
    </include>
    <include>
      <name>OpenRobotics/Chair_40</name>
      <uri>model://Chair</uri>
      <pose>24.684391091535176 -13.355873947386845 0.0 0 0 1.5708</pose>
      <static>True</static>
    </include>
    <include>
      <name>OpenRobotics/Chair_41</name>
      <uri>model://Chair</uri>
      <pose>25.31865138216143 -13.355873947386845 0.0 0 0 1.5708</pose>
      <static>True</static>
    </include>
    <include>
      <name>OpenRobotics/Chair_42</name>
      <uri>model://Chair</uri>
      <pose>15.578280047610257 -14.782959601295916 0.0 0 0 1.5708</pose>
      <static>True</static>
    </include>
    <include>
      <name>OpenRobotics/Chair_43</name>
      <uri>model://Chair</uri>
      <pose>16.189880910705305 -14.782959601295916 0.0 0 0 1.5708</pose>
      <static>True</static>
    </include>
    <include>
      <name>OpenRobotics/Chair_44</name>
      <uri>model://Chair</uri>
      <pose>17.050659096550802 -14.782959601295916 0.0 0 0 1.5708</pose>
      <static>True</static>
    </include>
    <include>
      <name>OpenRobotics/Chair_45</name>
      <uri>model://Chair</uri>
      <pose>17.684919387177057 -14.782959601295916 0.0 0 0 1.5708</pose>
      <static>True</static>
    </include>
    <include>
      <name>OpenRobotics/Chair_46</name>
      <uri>model://Chair</uri>
      <pose>19.406475758868044 -14.760300173764712 0.0 0 0 1.5708</pose>
      <static>True</static>
    </include>
    <include>
      <name>OpenRobotics/Chair_47</name>
      <uri>model://Chair</uri>
      <pose>20.0407360494943 -14.715006778733237 0.0 0 0 1.5708</pose>
      <static>True</static>
    </include>
    <include>
      <name>OpenRobotics/Chair_48</name>
      <uri>model://Chair</uri>
      <pose>20.856195380277388 -14.760300173764712 0.0 0 0 1.5708</pose>
      <static>True</static>
    </include>
    <include>
      <name>OpenRobotics/Chair_49</name>
      <uri>model://Chair</uri>
      <pose>21.581067920997523 -14.782959601295916 0.0 0 0 1.5708</pose>
      <static>True</static>
    </include>
    <include>
      <name>OpenRobotics/Chair_50</name>
      <uri>model://Chair</uri>
      <pose>23.144059220031952 -14.782959601295916 0.0 0 0 1.5708</pose>
      <static>True</static>
    </include>
    <include>
      <name>OpenRobotics/Chair_51</name>
      <uri>model://Chair</uri>
      <pose>23.7330006555958 -14.782959601295916 0.0 0 0 1.5708</pose>
      <static>True</static>
    </include>
    <include>
      <name>OpenRobotics/Chair_52</name>
      <uri>model://Chair</uri>
      <pose>24.6390976965037 -14.782959601295916 0.0 0 0 1.5708</pose>
      <static>True</static>
    </include>
    <include>
      <name>OpenRobotics/Chair_53</name>
      <uri>model://Chair</uri>
      <pose>25.341310809692633 -14.782959601295916 0.0 0 0 1.5708</pose>
      <static>True</static>
    </include>
    <include>
      <name>OpenRobotics/Chair_54</name>
      <uri>model://Chair</uri>
      <pose>15.600914015110527 -16.164726400142577 0.0 0 0 1.5708</pose>
      <static>True</static>
    </include>
    <include>
      <name>OpenRobotics/Chair_55</name>
      <uri>model://Chair</uri>
      <pose>16.28049316079919 -16.164726400142577 0.0 0 0 1.5708</pose>
      <static>True</static>
    </include>
    <include>
      <name>OpenRobotics/Chair_56</name>
      <uri>model://Chair</uri>
      <pose>17.095952491582278 -16.164726400142577 0.0 0 0 1.5708</pose>
      <static>True</static>
    </include>
    <include>
      <name>OpenRobotics/Chair_57</name>
      <uri>model://Chair</uri>
      <pose>17.707553354677326 -16.187385827673783 0.0 0 0 1.5708</pose>
      <static>True</static>
    </include>
    <include>
      <name>OpenRobotics/Chair_58</name>
      <uri>model://Chair</uri>
      <pose>19.383816331336842 -16.187385827673783 0.0 0 0 1.5708</pose>
      <static>True</static>
    </include>
    <include>
      <name>OpenRobotics/Chair_59</name>
      <uri>model://Chair</uri>
      <pose>20.018076621963097 -16.21001979517405 0.0 0 0 1.5708</pose>
      <static>True</static>
    </include>
    <include>
      <name>OpenRobotics/Chair_60</name>
      <uri>model://Chair</uri>
      <pose>20.833535952746182 -16.164726400142577 0.0 0 0 1.5708</pose>
      <static>True</static>
    </include>
    <include>
      <name>OpenRobotics/Chair_61</name>
      <uri>model://Chair</uri>
      <pose>21.49045567090364 -16.187385827673783 0.0 0 0 1.5708</pose>
      <static>True</static>
    </include>
    <include>
      <name>OpenRobotics/Chair_62</name>
      <uri>model://Chair</uri>
      <pose>23.098740364969544 -16.164726400142577 0.0 0 0 1.5708</pose>
      <static>True</static>
    </include>
    <include>
      <name>OpenRobotics/Chair_63</name>
      <uri>model://Chair</uri>
      <pose>23.7330006555958 -16.1194330051111 0.0 0 0 1.5708</pose>
      <static>True</static>
    </include>
    <include>
      <name>OpenRobotics/Chair_64</name>
      <uri>model://Chair</uri>
      <pose>24.72968448656665 -16.232679222705258 0.0 0 0 1.5708</pose>
      <static>True</static>
    </include>
    <include>
      <name>OpenRobotics/Chair_65</name>
      <uri>model://Chair</uri>
      <pose>25.363944777192906 -16.21001979517405 0.0 0 0 1.5708</pose>
      <static>True</static>
    </include>
    <include>
      <name>OpenRobotics/Chair_66</name>
      <uri>model://Chair</uri>
      <pose>15.600914015110527 -17.523859231488967 0.0 0 0 1.5708</pose>
      <static>True</static>
    </include>
    <include>
      <name>OpenRobotics/Chair_67</name>
      <uri>model://Chair</uri>
      <pose>16.23517430573678 -17.50119980395776 0.0 0 0 1.5708</pose>
      <static>True</static>
    </include>
    <include>
      <name>OpenRobotics/Chair_68</name>
      <uri>model://Chair</uri>
      <pose>17.050659096550802 -17.546493198989236 0.0 0 0 1.5708</pose>
      <static>True</static>
    </include>
    <include>
      <name>OpenRobotics/Chair_69</name>
      <uri>model://Chair</uri>
      <pose>17.684919387177057 -17.546493198989236 0.0 0 0 1.5708</pose>
      <static>True</static>
    </include>
    <include>
      <name>OpenRobotics/Chair_70</name>
      <uri>model://Chair</uri>
      <pose>19.383816331336842 -17.546493198989236 0.0 0 0 1.5708</pose>
      <static>True</static>
    </include>
    <include>
      <name>OpenRobotics/Chair_71</name>
      <uri>model://Chair</uri>
      <pose>19.99541719443189 -17.50119980395776 0.0 0 0 1.5708</pose>
      <static>True</static>
    </include>
    <include>
      <name>OpenRobotics/Chair_72</name>
      <uri>model://Chair</uri>
      <pose>20.833535952746182 -17.56915262652044 0.0 0 0 1.5708</pose>
      <static>True</static>
    </include>
    <include>
      <name>OpenRobotics/Chair_73</name>
      <uri>model://Chair</uri>
      <pose>21.49045567090364 -17.56915262652044 0.0 0 0 1.5708</pose>
      <static>True</static>
    </include>
    <include>
      <name>OpenRobotics/Chair_74</name>
      <uri>model://Chair</uri>
      <pose>23.144059220031952 -17.546493198989236 0.0 0 0 1.5708</pose>
      <static>True</static>
    </include>
    <include>
      <name>OpenRobotics/Chair_75</name>
      <uri>model://Chair</uri>
      <pose>23.800953478158476 -17.56915262652044 0.0 0 0 1.5708</pose>
      <static>True</static>
    </include>
    <include>
      <name>OpenRobotics/Chair_76</name>
      <uri>model://Chair</uri>
      <pose>24.6390976965037 -17.56915262652044 0.0 0 0 1.5708</pose>
      <static>True</static>
    </include>
    <include>
      <name>OpenRobotics/Chair_77</name>
      <uri>model://Chair</uri>
      <pose>25.31865138216143 -17.546493198989236 0.0 0 0 1.5708</pose>
      <static>True</static>
    </include>
    <include>
      <name>OpenRobotics/Chair_78</name>
      <uri>model://Chair</uri>
      <pose>15.623573442641732 -18.950919425367104 0.0 0 0 1.5708</pose>
      <static>True</static>
    </include>
    <include>
      <name>OpenRobotics/Chair_79</name>
      <uri>model://Chair</uri>
      <pose>16.257833733267987 -18.950919425367104 0.0 0 0 1.5708</pose>
      <static>True</static>
    </include>
    <include>
      <name>OpenRobotics/Chair_80</name>
      <uri>model://Chair</uri>
      <pose>16.98270627398812 -18.950919425367104 0.0 0 0 1.5708</pose>
      <static>True</static>
    </include>
    <include>
      <name>OpenRobotics/Chair_81</name>
      <uri>model://Chair</uri>
      <pose>17.707553354677326 -18.950919425367104 0.0 0 0 1.5708</pose>
      <static>True</static>
    </include>
    <include>
      <name>OpenRobotics/Chair_82</name>
      <uri>model://Chair</uri>
      <pose>19.338522936305367 -18.92828545786683 0.0 0 0 1.5708</pose>
      <static>True</static>
    </include>
    <include>
      <name>OpenRobotics/Chair_83</name>
      <uri>model://Chair</uri>
      <pose>19.97275776690069 -18.92828545786683 0.0 0 0 1.5708</pose>
      <static>True</static>
    </include>
    <include>
      <name>OpenRobotics/Chair_84</name>
      <uri>model://Chair</uri>
      <pose>20.810901985245913 -18.92828545786683 0.0 0 0 1.5708</pose>
      <static>True</static>
    </include>
    <include>
      <name>OpenRobotics/Chair_85</name>
      <uri>model://Chair</uri>
      <pose>21.513115098434845 -18.90562603033563 0.0 0 0 1.5708</pose>
      <static>True</static>
    </include>
    <include>
      <name>OpenRobotics/Chair_86</name>
      <uri>model://Chair</uri>
      <pose>23.098740364969544 -18.973578852898306 0.0 0 0 1.5708</pose>
      <static>True</static>
    </include>
    <include>
      <name>OpenRobotics/Chair_87</name>
      <uri>model://Chair</uri>
      <pose>23.710366688095526 -18.973578852898306 0.0 0 0 1.5708</pose>
      <static>True</static>
    </include>
    <include>
      <name>OpenRobotics/Chair_88</name>
      <uri>model://Chair</uri>
      <pose>24.593778841441292 -18.973578852898306 0.0 0 0 1.5708</pose>
      <static>True</static>
    </include>
    <include>
      <name>OpenRobotics/Chair_89</name>
      <uri>model://Chair</uri>
      <pose>25.273332527099022 -18.973578852898306 0.0 0 0 1.5708</pose>
      <static>True</static>
    </include>
    <include>
      <name>OpenRobotics/Chair_90</name>
      <uri>model://Chair</uri>
      <pose>15.555620620079052 -20.264733401651082 0.0 0 0 1.5708</pose>
      <static>True</static>
    </include>
    <include>
      <name>OpenRobotics/Chair_91</name>
      <uri>model://Chair</uri>
      <pose>16.23517430573678 -20.287392829182288 0.0 0 0 1.5708</pose>
      <static>True</static>
    </include>
    <include>
      <name>OpenRobotics/Chair_92</name>
      <uri>model://Chair</uri>
      <pose>17.005340241488394 -20.31005225671349 0.0 0 0 1.5708</pose>
      <static>True</static>
    </include>
    <include>
      <name>OpenRobotics/Chair_93</name>
      <uri>model://Chair</uri>
      <pose>17.707553354677326 -20.31005225671349 0.0 0 0 1.5708</pose>
      <static>True</static>
    </include>
    <include>
      <name>OpenRobotics/Chair_94</name>
      <uri>model://Chair</uri>
      <pose>19.429109726368317 -20.3327116842447 0.0 0 0 1.5708</pose>
      <static>True</static>
    </include>
    <include>
      <name>OpenRobotics/Chair_95</name>
      <uri>model://Chair</uri>
      <pose>20.0407360494943 -20.31005225671349 0.0 0 0 1.5708</pose>
      <static>True</static>
    </include>
    <include>
      <name>OpenRobotics/Chair_96</name>
      <uri>model://Chair</uri>
      <pose>20.833535952746182 -20.3327116842447 0.0 0 0 1.5708</pose>
      <static>True</static>
    </include>
    <include>
      <name>OpenRobotics/Chair_97</name>
      <uri>model://Chair</uri>
      <pose>21.55840849346632 -20.3327116842447 0.0 0 0 1.5708</pose>
      <static>True</static>
    </include>
    <include>
      <name>OpenRobotics/Chair_98</name>
      <uri>model://Chair</uri>
      <pose>23.121399792500746 -20.3327116842447 0.0 0 0 1.5708</pose>
      <static>True</static>
    </include>
    <include>
      <name>OpenRobotics/Chair_99</name>
      <uri>model://Chair</uri>
      <pose>23.823612905689682 -20.31005225671349 0.0 0 0 1.5708</pose>
      <static>True</static>
    </include>
    <include>
      <name>OpenRobotics/Chair_100</name>
      <uri>model://Chair</uri>
      <pose>24.661731664003973 -20.355345651744965 0.0 0 0 1.5708</pose>
      <static>True</static>
    </include>
    <include>
      <name>OpenRobotics/Chair_101</name>
      <uri>model://Chair</uri>
      <pose>25.31865138216143 -20.355345651744965 0.0 0 0 1.5708</pose>
      <static>True</static>
    </include>
    <include>
      <name>OpenRobotics/Chair_102</name>
      <uri>model://Chair</uri>
      <pose>15.64623287017294 -21.71447848309136 0.0 0 0 1.5708</pose>
      <static>True</static>
    </include>
    <include>
      <name>OpenRobotics/Chair_103</name>
      <uri>model://Chair</uri>
      <pose>16.325786555830664 -21.71447848309136 0.0 0 0 1.5708</pose>
      <static>True</static>
    </include>
    <include>
      <name>OpenRobotics/Chair_104</name>
      <uri>model://Chair</uri>
      <pose>17.095952491582278 -21.71447848309136 0.0 0 0 1.5708</pose>
      <static>True</static>
    </include>
    <include>
      <name>OpenRobotics/Chair_105</name>
      <uri>model://Chair</uri>
      <pose>17.730212782208532 -21.73713791062256 0.0 0 0 1.5708</pose>
      <static>True</static>
    </include>
    <include>
      <name>OpenRobotics/Chair_106</name>
      <uri>model://Chair</uri>
      <pose>19.383816331336842 -21.75977187812283 0.0 0 0 1.5708</pose>
      <static>True</static>
    </include>
    <include>
      <name>OpenRobotics/Chair_107</name>
      <uri>model://Chair</uri>
      <pose>20.018076621963097 -21.75977187812283 0.0 0 0 1.5708</pose>
      <static>True</static>
    </include>
    <include>
      <name>OpenRobotics/Chair_108</name>
      <uri>model://Chair</uri>
      <pose>20.87885480780859 -21.73713791062256 0.0 0 0 1.5708</pose>
      <static>True</static>
    </include>
    <include>
      <name>OpenRobotics/Chair_109</name>
      <uri>model://Chair</uri>
      <pose>21.535749065935114 -21.71447848309136 0.0 0 0 1.5708</pose>
      <static>True</static>
    </include>
    <include>
      <name>OpenRobotics/Chair_110</name>
      <uri>model://Chair</uri>
      <pose>23.144059220031952 -21.75977187812283 0.0 0 0 1.5708</pose>
      <static>True</static>
    </include>
    <include>
      <name>OpenRobotics/Chair_111</name>
      <uri>model://Chair</uri>
      <pose>23.755660083127 -21.71447848309136 0.0 0 0 1.5708</pose>
      <static>True</static>
    </include>
    <include>
      <name>OpenRobotics/Chair_112</name>
      <uri>model://Chair</uri>
      <pose>24.616438268972498 -21.75977187812283 0.0 0 0 1.5708</pose>
      <static>True</static>
    </include>
    <include>
      <name>OpenRobotics/Chair_113</name>
      <uri>model://Chair</uri>
      <pose>25.31865138216143 -21.782431305654036 0.0 0 0 1.5708</pose>
      <static>True</static>
    </include>
    <include>
      <name>OpenRobotics/Chair_114</name>
      <uri>model://Chair</uri>
      <pose>15.600914015110527 -23.096245281938018 0.0 0 0 1.5708</pose>
      <static>True</static>
    </include>
    <include>
      <name>OpenRobotics/Chair_115</name>
      <uri>model://Chair</uri>
      <pose>16.21254033823651 -23.118904709469223 0.0 0 0 1.5708</pose>
      <static>True</static>
    </include>
    <include>
      <name>OpenRobotics/Chair_116</name>
      <uri>model://Chair</uri>
      <pose>17.005340241488394 -23.141564137000426 0.0 0 0 1.5708</pose>
      <static>True</static>
    </include>
    <include>
      <name>OpenRobotics/Chair_117</name>
      <uri>model://Chair</uri>
      <pose>17.684919387177057 -23.118904709469223 0.0 0 0 1.5708</pose>
      <static>True</static>
    </include>
    <include>
      <name>OpenRobotics/Chair_118</name>
      <uri>model://Chair</uri>
      <pose>19.383816331336842 -23.118904709469223 0.0 0 0 1.5708</pose>
      <static>True</static>
    </include>
    <include>
      <name>OpenRobotics/Chair_119</name>
      <uri>model://Chair</uri>
      <pose>20.0407360494943 -23.118904709469223 0.0 0 0 1.5708</pose>
      <static>True</static>
    </include>
    <include>
      <name>OpenRobotics/Chair_120</name>
      <uri>model://Chair</uri>
      <pose>20.924148202840065 -23.096245281938018 0.0 0 0 1.5708</pose>
      <static>True</static>
    </include>
    <include>
      <name>OpenRobotics/Chair_121</name>
      <uri>model://Chair</uri>
      <pose>21.603701888497795 -23.118904709469223 0.0 0 0 1.5708</pose>
      <static>True</static>
    </include>
    <include>
      <name>OpenRobotics/Chair_122</name>
      <uri>model://Chair</uri>
      <pose>23.121399792500746 -23.1641981045007 0.0 0 0 1.5708</pose>
      <static>True</static>
    </include>
    <include>
      <name>OpenRobotics/Chair_123</name>
      <uri>model://Chair</uri>
      <pose>23.846272333220885 -23.141564137000426 0.0 0 0 1.5708</pose>
      <static>True</static>
    </include>
    <include>
      <name>OpenRobotics/Chair_124</name>
      <uri>model://Chair</uri>
      <pose>24.684391091535176 -23.096245281938018 0.0 0 0 1.5708</pose>
      <static>True</static>
    </include>
    <include>
      <name>OpenRobotics/Chair_125</name>
      <uri>model://Chair</uri>
      <pose>25.431897599755583 -23.141564137000426 0.0 0 0 1.5708</pose>
      <static>True</static>
    </include>
    <include>
      <name>OpenRobotics/Chair_126</name>
      <uri>model://Chair</uri>
      <pose>15.578280047610257 -24.63657715344124 0.0 0 0 1.5708</pose>
      <static>True</static>
    </include>
    <include>
      <name>OpenRobotics/Chair_127</name>
      <uri>model://Chair</uri>
      <pose>16.23517430573678 -24.59128375840977 0.0 0 0 1.5708</pose>
      <static>True</static>
    </include>
    <include>
      <name>OpenRobotics/Chair_128</name>
      <uri>model://Chair</uri>
      <pose>17.005340241488394 -24.59128375840977 0.0 0 0 1.5708</pose>
      <static>True</static>
    </include>
    <include>
      <name>OpenRobotics/Chair_129</name>
      <uri>model://Chair</uri>
      <pose>17.707553354677326 -24.568624330878563 0.0 0 0 1.5708</pose>
      <static>True</static>
    </include>
    <include>
      <name>OpenRobotics/Chair_130</name>
      <uri>model://Chair</uri>
      <pose>19.383816331336842 -24.613943185940972 0.0 0 0 1.5708</pose>
      <static>True</static>
    </include>
    <include>
      <name>OpenRobotics/Chair_131</name>
      <uri>model://Chair</uri>
      <pose>20.0407360494943 -24.568624330878563 0.0 0 0 1.5708</pose>
      <static>True</static>
    </include>
    <include>
      <name>OpenRobotics/Chair_132</name>
      <uri>model://Chair</uri>
      <pose>20.833535952746182 -24.545990363378294 0.0 0 0 1.5708</pose>
      <static>True</static>
    </include>
    <include>
      <name>OpenRobotics/Chair_133</name>
      <uri>model://Chair</uri>
      <pose>21.603701888497795 -24.545990363378294 0.0 0 0 1.5708</pose>
      <static>True</static>
    </include>
    <include>
      <name>OpenRobotics/Chair_134</name>
      <uri>model://Chair</uri>
      <pose>23.16669318753222 -24.59128375840977 0.0 0 0 1.5708</pose>
      <static>True</static>
    </include>
    <include>
      <name>OpenRobotics/Chair_135</name>
      <uri>model://Chair</uri>
      <pose>23.868906300721157 -24.59128375840977 0.0 0 0 1.5708</pose>
      <static>True</static>
    </include>
    <include>
      <name>OpenRobotics/Chair_136</name>
      <uri>model://Chair</uri>
      <pose>24.707050519066378 -24.568624330878563 0.0 0 0 1.5708</pose>
      <static>True</static>
    </include>
    <include>
      <name>OpenRobotics/Chair_137</name>
      <uri>model://Chair</uri>
      <pose>25.341310809692633 -24.568624330878563 0.0 0 0 1.5708</pose>
      <static>True</static>
    </include>
    <include>
      <name>OpenRobotics/Chair_138</name>
      <uri>model://Chair</uri>
      <pose>16.371105410893072 -8.734852872846242 0.0 0 0 1.9179</pose>
      <static>True</static>
    </include>
    <include>
      <name>tinyRobot1</name>
      <uri>model://TinyRobot</uri>
      <pose>14.026694842434232 -10.407347764927534 0.0 0 0 -1.5696228804800483</pose>
    </include>
    <model name="door1">
      <pose>18.842917974145337 -31.723924154567847 0.0 0 0 -0.003592788182383454</pose>
      <link name="right">
        <pose>0.7104158282135676 0 1.11 0 0 0</pose>
        <visual name="right_visual">
          <geometry>
            <box>
              <size>1.4108316564271353 0.03 2.2</size>
            </box>
          </geometry>
          <material>
            <ambient>0.5 0.25 0 0.6</ambient>
            <diffuse>0.5 0.25 0 0.6</diffuse>
            <pbr>
              <metal>
                <metalness>0.0</metalness>
              </metal>
            </pbr>
          </material>
        </visual>
        <collision name="right_collision">
          <geometry>
            <box>
              <size>1.4108316564271353 0.03 2.2</size>
            </box>
          </geometry>
          <surface>
            <contact>
              <collide_bitmask>0x02</collide_bitmask>
            </contact>
          </surface>
        </collision>
        <inertial>
          <mass>50.0</mass>
          <inertia>
            <ixx>20.17041666666667</ixx>
            <iyy>28.460191511570564</iyy>
            <izz>8.297274844903892</izz>
          </inertia>
        </inertial>
      </link>
      <joint name="right_joint" type="revolute">
        <parent>world</parent>
        <child>right</child>
        <axis>
          <xyz>0 0 1</xyz>
          <limit>
            <lower>0</lower>
            <upper>1.57</upper>
          </limit>
        </axis>
        <pose>0.7104158282135676 0 0 0 0 0</pose>
      </joint>
      <link name="left">
        <pose>-0.7104158282135676 0 1.11 0 0 0</pose>
        <visual name="left_visual">
          <geometry>
            <box>
              <size>1.4108316564271353 0.03 2.2</size>
            </box>
          </geometry>
          <material>
            <ambient>0.5 0.25 0 0.6</ambient>
            <diffuse>0.5 0.25 0 0.6</diffuse>
            <pbr>
              <metal>
                <metalness>0.0</metalness>
              </metal>
            </pbr>
          </material>
        </visual>
        <collision name="left_collision">
          <geometry>
            <box>
              <size>1.4108316564271353 0.03 2.2</size>
            </box>
          </geometry>
          <surface>
            <contact>
              <collide_bitmask>0x02</collide_bitmask>
            </contact>
          </surface>
        </collision>
        <inertial>
          <mass>50.0</mass>
          <inertia>
            <ixx>20.17041666666667</ixx>
            <iyy>28.460191511570564</iyy>
            <izz>8.297274844903892</izz>
          </inertia>
        </inertial>
      </link>
      <joint name="left_joint" type="revolute">
        <parent>world</parent>
        <child>left</child>
        <axis>
          <xyz>0 0 1</xyz>
          <limit>
            <lower>-1.57</lower>
            <upper>0</upper>
          </limit>
        </axis>
        <pose>-0.7104158282135676 0 0 0 0 0</pose>
      </joint>
      <plugin name="register_component" filename="libregister_component.so">
        <component name="Door">
          <v_max_door>0.5</v_max_door>
          <a_max_door>0.3</a_max_door>
          <a_nom_door>0.15</a_nom_door>
          <dx_min_door>0.01</dx_min_door>
          <f_max_door>500.0</f_max_door>
          <ros_interface>true</ros_interface>
          <door name="door1" type="DoubleSwingDoor" left_joint_name="left_joint" right_joint_name="right_joint" />
        </component>
      </plugin>
    </model>
    <model name="door2">
      <pose>22.032232399162368 -31.718819418365594 0.0 0 0 3.141592653589793</pose>
      <link name="right">
        <pose>0.707604274739194 0 1.11 0 0 0</pose>
        <visual name="right_visual">
          <geometry>
            <box>
              <size>1.405208549478388 0.03 2.2</size>
            </box>
          </geometry>
          <material>
            <ambient>0.5 0.25 0 0.6</ambient>
            <diffuse>0.5 0.25 0 0.6</diffuse>
            <pbr>
              <metal>
                <metalness>0.0</metalness>
              </metal>
            </pbr>
          </material>
        </visual>
        <collision name="right_collision">
          <geometry>
            <box>
              <size>1.405208549478388 0.03 2.2</size>
            </box>
          </geometry>
          <surface>
            <contact>
              <collide_bitmask>0x02</collide_bitmask>
            </contact>
          </surface>
        </collision>
        <inertial>
          <mass>50.0</mass>
          <inertia>
            <ixx>20.17041666666667</ixx>
            <iyy>28.39421278136315</iyy>
            <izz>8.231296114696478</izz>
          </inertia>
        </inertial>
      </link>
      <joint name="right_joint" type="revolute">
        <parent>world</parent>
        <child>right</child>
        <axis>
          <xyz>0 0 -1</xyz>
          <limit>
            <lower>0</lower>
            <upper>1.57</upper>
          </limit>
        </axis>
        <pose>0.707604274739194 0 0 0 0 0</pose>
      </joint>
      <link name="left">
        <pose>-0.707604274739194 0 1.11 0 0 0</pose>
        <visual name="left_visual">
          <geometry>
            <box>
              <size>1.405208549478388 0.03 2.2</size>
            </box>
          </geometry>
          <material>
            <ambient>0.5 0.25 0 0.6</ambient>
            <diffuse>0.5 0.25 0 0.6</diffuse>
            <pbr>
              <metal>
                <metalness>0.0</metalness>
              </metal>
            </pbr>
          </material>
        </visual>
        <collision name="left_collision">
          <geometry>
            <box>
              <size>1.405208549478388 0.03 2.2</size>
            </box>
          </geometry>
          <surface>
            <contact>
              <collide_bitmask>0x02</collide_bitmask>
            </contact>
          </surface>
        </collision>
        <inertial>
          <mass>50.0</mass>
          <inertia>
            <ixx>20.17041666666667</ixx>
            <iyy>28.39421278136315</iyy>
            <izz>8.231296114696478</izz>
          </inertia>
        </inertial>
      </link>
      <joint name="left_joint" type="revolute">
        <parent>world</parent>
        <child>left</child>
        <axis>
          <xyz>0 0 -1</xyz>
          <limit>
            <lower>-1.57</lower>
            <upper>0</upper>
          </limit>
        </axis>
        <pose>-0.707604274739194 0 0 0 0 0</pose>
      </joint>
      <plugin name="register_component" filename="libregister_component.so">
        <component name="Door">
          <v_max_door>0.5</v_max_door>
          <a_max_door>0.3</a_max_door>
          <a_nom_door>0.15</a_nom_door>
          <dx_min_door>0.01</dx_min_door>
          <f_max_door>500.0</f_max_door>
          <ros_interface>true</ros_interface>
          <door name="door2" type="DoubleSwingDoor" left_joint_name="left_joint" right_joint_name="right_joint" />
        </component>
      </plugin>
    </model>
    <model name="door3">
      <pose>17.041875385878594 -34.91931079696262 0.0 0 0 1.5707963267948966</pose>
      <link name="right">
        <pose>0 0 1.11 0 0 0</pose>
        <visual name="right_visual">
          <geometry>
            <box>
              <size>0.7135486191115683 0.03 2.2</size>
            </box>
          </geometry>
          <material>
            <ambient>0.5 0.25 0 0.6</ambient>
            <diffuse>0.5 0.25 0 0.6</diffuse>
            <pbr>
              <metal>
                <metalness>0.0</metalness>
              </metal>
            </pbr>
          </material>
        </visual>
        <collision name="right_collision">
          <geometry>
            <box>
              <size>0.7135486191115683 0.03 2.2</size>
            </box>
          </geometry>
          <surface>
            <contact>
              <collide_bitmask>0x02</collide_bitmask>
            </contact>
          </surface>
        </collision>
        <inertial>
          <mass>50.0</mass>
          <inertia>
            <ixx>20.17041666666667</ixx>
            <iyy>22.28813179931678</iyy>
            <izz>2.1252151326501085</izz>
          </inertia>
        </inertial>
      </link>
      <joint name="right_joint" type="revolute">
        <parent>world</parent>
        <child>right</child>
        <axis>
          <xyz>0 0 1</xyz>
          <limit>
            <lower>0</lower>
            <upper>1.57</upper>
          </limit>
        </axis>
        <pose>0.36177430955578416 0 0 0 0 0</pose>
      </joint>
      <plugin name="register_component" filename="libregister_component.so">
        <component name="Door">
          <v_max_door>0.5</v_max_door>
          <a_max_door>0.3</a_max_door>
          <a_nom_door>0.15</a_nom_door>
          <dx_min_door>0.01</dx_min_door>
          <f_max_door>500.0</f_max_door>
          <ros_interface>true</ros_interface>
          <door name="door3" type="SwingDoor" left_joint_name="empty_joint" right_joint_name="right_joint" />
        </component>
      </plugin>
    </model>
    <model name="door4">
      <pose>16.944503497571752 -43.24904365758805 0.0 0 0 1.5541321529719907</pose>
      <link name="right">
        <pose>0.33499231367601323 0 1.11 0 0 0</pose>
        <visual name="right_visual">
          <geometry>
            <box>
              <size>0.6599846273520265 0.03 2.2</size>
            </box>
          </geometry>
          <material>
            <ambient>0.5 0.25 0 0.6</ambient>
            <diffuse>0.5 0.25 0 0.6</diffuse>
            <pbr>
              <metal>
                <metalness>0.0</metalness>
              </metal>
            </pbr>
          </material>
        </visual>
        <collision name="right_collision">
          <geometry>
            <box>
              <size>0.6599846273520265 0.03 2.2</size>
            </box>
          </geometry>
          <surface>
            <contact>
              <collide_bitmask>0x02</collide_bitmask>
            </contact>
          </surface>
        </collision>
        <inertial>
          <mass>50.0</mass>
          <inertia>
            <ixx>20.17041666666667</ixx>
            <iyy>21.981582118087477</iyy>
            <izz>1.8186654514208054</izz>
          </inertia>
        </inertial>
      </link>
      <joint name="right_joint" type="revolute">
        <parent>world</parent>
        <child>right</child>
        <axis>
          <xyz>0 0 1</xyz>
          <limit>
            <lower>0</lower>
            <upper>1.57</upper>
          </limit>
        </axis>
        <pose>0.33499231367601323 0 0 0 0 0</pose>
      </joint>
      <link name="left">
        <pose>-0.33499231367601323 0 1.11 0 0 0</pose>
        <visual name="left_visual">
          <geometry>
            <box>
              <size>0.6599846273520265 0.03 2.2</size>
            </box>
          </geometry>
          <material>
            <ambient>0.5 0.25 0 0.6</ambient>
            <diffuse>0.5 0.25 0 0.6</diffuse>
            <pbr>
              <metal>
                <metalness>0.0</metalness>
              </metal>
            </pbr>
          </material>
        </visual>
        <collision name="left_collision">
          <geometry>
            <box>
              <size>0.6599846273520265 0.03 2.2</size>
            </box>
          </geometry>
          <surface>
            <contact>
              <collide_bitmask>0x02</collide_bitmask>
            </contact>
          </surface>
        </collision>
        <inertial>
          <mass>50.0</mass>
          <inertia>
            <ixx>20.17041666666667</ixx>
            <iyy>21.981582118087477</iyy>
            <izz>1.8186654514208054</izz>
          </inertia>
        </inertial>
      </link>
      <joint name="left_joint" type="revolute">
        <parent>world</parent>
        <child>left</child>
        <axis>
          <xyz>0 0 1</xyz>
          <limit>
            <lower>-1.57</lower>
            <upper>0</upper>
          </limit>
        </axis>
        <pose>-0.33499231367601323 0 0 0 0 0</pose>
      </joint>
      <plugin name="register_component" filename="libregister_component.so">
        <component name="Door">
          <v_max_door>0.5</v_max_door>
          <a_max_door>0.3</a_max_door>
          <a_nom_door>0.15</a_nom_door>
          <dx_min_door>0.01</dx_min_door>
          <f_max_door>500.0</f_max_door>
          <ros_interface>true</ros_interface>
          <door name="door4" type="DoubleSwingDoor" left_joint_name="left_joint" right_joint_name="right_joint" />
        </component>
      </plugin>
    </model>
    <include>
      <name>roomB_def_L1</name>
      <uri>model://roomB_def_L1</uri>
      <pose>0 0 0.0 0 0 0</pose>
    </include>
    <include>
      <name>OpenRobotics/AdjTable_65</name>
      <uri>model://AdjTable</uri>
      <pose>15.764741849611687 -23.945690349908475 8.0 0 0 -0.002180027777166466</pose>
      <static>True</static>
    </include>
    <include>
      <name>OpenRobotics/AdjTable_66</name>
      <uri>model://AdjTable</uri>
      <pose>17.331515269207383 -23.894171294212544 8.0 0 0 -0.002180027777166466</pose>
      <static>True</static>
    </include>
    <include>
      <name>OpenRobotics/AdjTable_67</name>
      <uri>model://AdjTable</uri>
      <pose>19.64382335980733 -23.864430469886475 8.0 0 0 -0.002180027777166466</pose>
      <static>True</static>
    </include>
    <include>
      <name>OpenRobotics/AdjTable_68</name>
      <uri>model://AdjTable</uri>
      <pose>21.191079076537612 -23.88519439976016 8.0 0 0 -0.002180027777166466</pose>
      <static>True</static>
    </include>
    <include>
      <name>OpenRobotics/AdjTable_69</name>
      <uri>model://AdjTable</uri>
      <pose>23.53797916778223 -23.942483307522362 8.0 0 0 -0.002180027777166466</pose>
      <static>True</static>
    </include>
    <include>
      <name>OpenRobotics/AdjTable_70</name>
      <uri>model://AdjTable</uri>
      <pose>24.928693231779043 -23.997662125082662 8.0 0 0 -0.002180027777166466</pose>
      <static>True</static>
    </include>
    <include>
      <name>OpenRobotics/AdjTable_71</name>
      <uri>model://AdjTable</uri>
      <pose>23.47147366462677 -22.5515039679061 8.0 0 0 -0.002180027777166466</pose>
      <static>True</static>
    </include>
    <include>
      <name>OpenRobotics/AdjTable_72</name>
      <uri>model://AdjTable</uri>
      <pose>24.966557037040086 -22.57215416043979 8.0 0 0 -0.002180027777166466</pose>
      <static>True</static>
    </include>
    <include>
      <name>OpenRobotics/AdjTable_73</name>
      <uri>model://AdjTable</uri>
      <pose>21.193959474672877 -22.563929779932906 8.0 0 0 -0.002180027777166466</pose>
      <static>True</static>
    </include>
    <include>
      <name>OpenRobotics/AdjTable_74</name>
      <uri>model://AdjTable</uri>
      <pose>19.668155154433375 -22.55758565244733 8.0 0 0 -0.002180027777166466</pose>
      <static>True</static>
    </include>
    <include>
      <name>OpenRobotics/AdjTable_75</name>
      <uri>model://AdjTable</uri>
      <pose>17.40397113086668 -22.55566748697936 8.0 0 0 -0.002180027777166466</pose>
      <static>True</static>
    </include>
    <include>
      <name>OpenRobotics/AdjTable_76</name>
      <uri>model://AdjTable</uri>
      <pose>15.821782257225362 -22.604365283289727 8.0 0 0 -0.002180027777166466</pose>
      <static>True</static>
    </include>
    <include>
      <name>OpenRobotics/Chair_139</name>
      <uri>model://Chair</uri>
      <pose>15.614305702868034 -23.0447458077854 8.0 0 0 1.5686199722228336</pose>
      <static>True</static>
    </include>
    <include>
      <name>OpenRobotics/Chair_140</name>
      <uri>model://Chair</uri>
      <pose>16.10376825364372 -23.062692219519036 8.0 0 0 1.5686199722228336</pose>
      <static>True</static>
    </include>
    <include>
      <name>OpenRobotics/Chair_141</name>
      <uri>model://Chair</uri>
      <pose>17.099671812490342 -23.064863320380105 8.0 0 0 1.5686199722228336</pose>
      <static>True</static>
    </include>
    <include>
      <name>OpenRobotics/Chair_142</name>
      <uri>model://Chair</uri>
      <pose>17.673530802602304 -23.082993718987257 8.0 0 0 1.5686199722228336</pose>
      <static>True</static>
    </include>
    <include>
      <name>OpenRobotics/Chair_143</name>
      <uri>model://Chair</uri>
      <pose>19.39507097556348 -23.154264202675964 8.0 0 0 1.5686199722228336</pose>
      <static>True</static>
    </include>
    <include>
      <name>OpenRobotics/Chair_144</name>
      <uri>model://Chair</uri>
      <pose>19.985919645666804 -23.121793535056057 8.0 0 0 1.5686199722228336</pose>
      <static>True</static>
    </include>
    <include>
      <name>OpenRobotics/Chair_145</name>
      <uri>model://Chair</uri>
      <pose>20.914342850419107 -23.106938158551056 8.0 0 0 1.5686199722228336</pose>
      <static>True</static>
    </include>
    <include>
      <name>OpenRobotics/Chair_146</name>
      <uri>model://Chair</uri>
      <pose>21.505081128398324 -23.125105354532913 8.0 0 0 1.5686199722228336</pose>
      <static>True</static>
    </include>
    <include>
      <name>OpenRobotics/Chair_147</name>
      <uri>model://Chair</uri>
      <pose>23.26055264127141 -23.12893233725561 8.0 0 0 1.5686199722228336</pose>
      <static>True</static>
    </include>
    <include>
      <name>OpenRobotics/Chair_148</name>
      <uri>model://Chair</uri>
      <pose>23.800689853023563 -23.1301098532461 8.0 0 0 1.5686199722228336</pose>
      <static>True</static>
    </include>
    <include>
      <name>OpenRobotics/Chair_149</name>
      <uri>model://Chair</uri>
      <pose>24.71217139785532 -23.132096911480055 8.0 0 0 1.5686199722228336</pose>
      <static>True</static>
    </include>
    <include>
      <name>OpenRobotics/Chair_150</name>
      <uri>model://Chair</uri>
      <pose>25.319825761076494 -23.133421616969358 8.0 0 0 1.5686199722228336</pose>
      <static>True</static>
    </include>
    <include>
      <name>OpenRobotics/Chair_151</name>
      <uri>model://Chair</uri>
      <pose>23.223703086061857 -24.546718923355606 8.0 0 0 1.5686199722228336</pose>
      <static>True</static>
    </include>
    <include>
      <name>OpenRobotics/Chair_152</name>
      <uri>model://Chair</uri>
      <pose>23.730081722079504 -24.54782284459669 8.0 0 0 1.5686199722228336</pose>
      <static>True</static>
    </include>
    <include>
      <name>OpenRobotics/Chair_153</name>
      <uri>model://Chair</uri>
      <pose>24.692164333138326 -24.566799582822007 8.0 0 0 1.5686199722228336</pose>
      <static>True</static>
    </include>
    <include>
      <name>OpenRobotics/Chair_154</name>
      <uri>model://Chair</uri>
      <pose>25.282939408492247 -24.568087490936605 8.0 0 0 1.5686199722228336</pose>
      <static>True</static>
    </include>
    <include>
      <name>OpenRobotics/Chair_155</name>
      <uri>model://Chair</uri>
      <pose>20.92805756406192 -24.558593712509673 8.0 0 0 1.5686199722228336</pose>
      <static>True</static>
    </include>
    <include>
      <name>OpenRobotics/Chair_156</name>
      <uri>model://Chair</uri>
      <pose>21.468231573188774 -24.54289194063291 8.0 0 0 1.5686199722228336</pose>
      <static>True</static>
    </include>
    <include>
      <name>OpenRobotics/Chair_157</name>
      <uri>model://Chair</uri>
      <pose>19.42573857182295 -24.572197978274776 8.0 0 0 1.5686199722228336</pose>
      <static>True</static>
    </include>
    <include>
      <name>OpenRobotics/Chair_158</name>
      <uri>model://Chair</uri>
      <pose>19.999671156684315 -24.55656980114742 8.0 0 0 1.5686199722228336</pose>
      <static>True</static>
    </include>
    <include>
      <name>OpenRobotics/Chair_159</name>
      <uri>model://Chair</uri>
      <pose>17.06263827040728 -24.567046345816376 8.0 0 0 1.5686199722228336</pose>
      <static>True</static>
    </include>
    <include>
      <name>OpenRobotics/Chair_160</name>
      <uri>model://Chair</uri>
      <pose>17.636570855268644 -24.551418168689015 8.0 0 0 1.5686199722228336</pose>
      <static>True</static>
    </include>
    <include>
      <name>OpenRobotics/Chair_161</name>
      <uri>model://Chair</uri>
      <pose>15.560356075543014 -24.563771323714224 8.0 0 0 1.5686199722228336</pose>
      <static>True</static>
    </include>
    <include>
      <name>OpenRobotics/Chair_162</name>
      <uri>model://Chair</uri>
      <pose>16.13428866040438 -24.548143146586863 8.0 0 0 1.5686199722228336</pose>
      <static>True</static>
    </include>
    <include>
      <name>OpenRobotics/Chair_163</name>
      <uri>model://Chair</uri>
      <pose>14.094427599677353 -33.70551028561695 8.0 0 0 1.5686199722228336</pose>
      <static>True</static>
    </include>
    <include>
      <name>OpenRobotics/Chair_164</name>
      <uri>model://Chair</uri>
      <pose>14.694563007394022 -33.706818599548434 8.0 0 0 1.5686199722228336</pose>
      <static>True</static>
    </include>
    <include>
      <name>OpenRobotics/Chair_165</name>
      <uri>model://Chair</uri>
      <pose>15.174702023181663 -33.707865317597935 8.0 0 0 1.5686199722228336</pose>
      <static>True</static>
    </include>
    <include>
      <name>OpenRobotics/AdjTable_77</name>
      <uri>model://AdjTable</uri>
      <pose>14.618128383732035 -32.81135494148412 8.0 0 0 -0.002180027777166466</pose>
      <static>True</static>
    </include>
    <model name="door6">
      <pose>18.78676646756648 -31.65727521792319 8.0 0 0 -0.0021800277771673146</pose>
      <link name="right">
        <pose>0.7002427573334377 0 1.11 0 0 0</pose>
        <visual name="right_visual">
          <geometry>
            <box>
              <size>1.3904855146668753 0.03 2.2</size>
            </box>
          </geometry>
          <material>
            <ambient>0.5 0.25 0 0.6</ambient>
            <diffuse>0.5 0.25 0 0.6</diffuse>
            <pbr>
              <metal>
                <metalness>0.0</metalness>
              </metal>
            </pbr>
          </material>
        </visual>
        <collision name="right_collision">
          <geometry>
            <box>
              <size>1.3904855146668753 0.03 2.2</size>
            </box>
          </geometry>
          <surface>
            <contact>
              <collide_bitmask>0x02</collide_bitmask>
            </contact>
          </surface>
        </collision>
        <inertial>
          <mass>50.0</mass>
          <inertia>
            <ixx>20.17041666666667</ixx>
            <iyy>28.22270819374336</iyy>
            <izz>8.059791527076689</izz>
          </inertia>
        </inertial>
      </link>
      <joint name="right_joint" type="revolute">
        <parent>world</parent>
        <child>right</child>
        <axis>
          <xyz>0 0 1</xyz>
          <limit>
            <lower>0</lower>
            <upper>1.57</upper>
          </limit>
        </axis>
        <pose>0.7002427573334377 0 0 0 0 0</pose>
      </joint>
      <link name="left">
        <pose>-0.7002427573334377 0 1.11 0 0 0</pose>
        <visual name="left_visual">
          <geometry>
            <box>
              <size>1.3904855146668753 0.03 2.2</size>
            </box>
          </geometry>
          <material>
            <ambient>0.5 0.25 0 0.6</ambient>
            <diffuse>0.5 0.25 0 0.6</diffuse>
            <pbr>
              <metal>
                <metalness>0.0</metalness>
              </metal>
            </pbr>
          </material>
        </visual>
        <collision name="left_collision">
          <geometry>
            <box>
              <size>1.3904855146668753 0.03 2.2</size>
            </box>
          </geometry>
          <surface>
            <contact>
              <collide_bitmask>0x02</collide_bitmask>
            </contact>
          </surface>
        </collision>
        <inertial>
          <mass>50.0</mass>
          <inertia>
            <ixx>20.17041666666667</ixx>
            <iyy>28.22270819374336</iyy>
            <izz>8.059791527076689</izz>
          </inertia>
        </inertial>
      </link>
      <joint name="left_joint" type="revolute">
        <parent>world</parent>
        <child>left</child>
        <axis>
          <xyz>0 0 1</xyz>
          <limit>
            <lower>-1.57</lower>
            <upper>0</upper>
          </limit>
        </axis>
        <pose>-0.7002427573334377 0 0 0 0 0</pose>
      </joint>
      <plugin name="register_component" filename="libregister_component.so">
        <component name="Door">
          <v_max_door>0.5</v_max_door>
          <a_max_door>0.3</a_max_door>
          <a_nom_door>0.15</a_nom_door>
          <dx_min_door>0.01</dx_min_door>
          <f_max_door>500.0</f_max_door>
          <ros_interface>true</ros_interface>
          <door name="door6" type="DoubleSwingDoor" left_joint_name="left_joint" right_joint_name="right_joint" />
        </component>
      </plugin>
    </model>
    <model name="door7">
      <pose>21.99220717025463 -31.66426317876326 8.0 0 0 3.1394126258126276</pose>
      <link name="right">
        <pose>0.7068090716638525 0 1.11 0 0 0</pose>
        <visual name="right_visual">
          <geometry>
            <box>
              <size>1.403618143327705 0.03 2.2</size>
            </box>
          </geometry>
          <material>
            <ambient>0.5 0.25 0 0.6</ambient>
            <diffuse>0.5 0.25 0 0.6</diffuse>
            <pbr>
              <metal>
                <metalness>0.0</metalness>
              </metal>
            </pbr>
          </material>
        </visual>
        <collision name="right_collision">
          <geometry>
            <box>
              <size>1.403618143327705 0.03 2.2</size>
            </box>
          </geometry>
          <surface>
            <contact>
              <collide_bitmask>0x02</collide_bitmask>
            </contact>
          </surface>
        </collision>
        <inertial>
          <mass>50.0</mass>
          <inertia>
            <ixx>20.17041666666667</ixx>
            <iyy>28.375599551161315</iyy>
            <izz>8.212682884494642</izz>
          </inertia>
        </inertial>
      </link>
      <joint name="right_joint" type="revolute">
        <parent>world</parent>
        <child>right</child>
        <axis>
          <xyz>0 0 -1</xyz>
          <limit>
            <lower>0</lower>
            <upper>1.57</upper>
          </limit>
        </axis>
        <pose>0.7068090716638525 0 0 0 0 0</pose>
      </joint>
      <link name="left">
        <pose>-0.7068090716638525 0 1.11 0 0 0</pose>
        <visual name="left_visual">
          <geometry>
            <box>
              <size>1.403618143327705 0.03 2.2</size>
            </box>
          </geometry>
          <material>
            <ambient>0.5 0.25 0 0.6</ambient>
            <diffuse>0.5 0.25 0 0.6</diffuse>
            <pbr>
              <metal>
                <metalness>0.0</metalness>
              </metal>
            </pbr>
          </material>
        </visual>
        <collision name="left_collision">
          <geometry>
            <box>
              <size>1.403618143327705 0.03 2.2</size>
            </box>
          </geometry>
          <surface>
            <contact>
              <collide_bitmask>0x02</collide_bitmask>
            </contact>
          </surface>
        </collision>
        <inertial>
          <mass>50.0</mass>
          <inertia>
            <ixx>20.17041666666667</ixx>
            <iyy>28.375599551161315</iyy>
            <izz>8.212682884494642</izz>
          </inertia>
        </inertial>
      </link>
      <joint name="left_joint" type="revolute">
        <parent>world</parent>
        <child>left</child>
        <axis>
          <xyz>0 0 -1</xyz>
          <limit>
            <lower>-1.57</lower>
            <upper>0</upper>
          </limit>
        </axis>
        <pose>-0.7068090716638525 0 0 0 0 0</pose>
      </joint>
      <plugin name="register_component" filename="libregister_component.so">
        <component name="Door">
          <v_max_door>0.5</v_max_door>
          <a_max_door>0.3</a_max_door>
          <a_nom_door>0.15</a_nom_door>
          <dx_min_door>0.01</dx_min_door>
          <f_max_door>500.0</f_max_door>
          <ros_interface>true</ros_interface>
          <door name="door7" type="DoubleSwingDoor" left_joint_name="left_joint" right_joint_name="right_joint" />
        </component>
      </plugin>
    </model>
    <model name="door5">
      <pose>16.954624670447203 -34.931011413418545 8.0 0 0 1.568616299017729</pose>
      <link name="right">
        <pose>0 0 1.11 0 0 0</pose>
        <visual name="right_visual">
          <geometry>
            <box>
              <size>0.7084200033328207 0.03 2.2</size>
            </box>
          </geometry>
          <material>
            <ambient>0.5 0.25 0 0.6</ambient>
            <diffuse>0.5 0.25 0 0.6</diffuse>
            <pbr>
              <metal>
                <metalness>0.0</metalness>
              </metal>
            </pbr>
          </material>
        </visual>
        <collision name="right_collision">
          <geometry>
            <box>
              <size>0.7084200033328207 0.03 2.2</size>
            </box>
          </geometry>
          <surface>
            <contact>
              <collide_bitmask>0x02</collide_bitmask>
            </contact>
          </surface>
        </collision>
        <inertial>
          <mass>50.0</mass>
          <inertia>
            <ixx>20.17041666666667</ixx>
            <iyy>22.25774542134198</iyy>
            <izz>2.0948287546753077</izz>
          </inertia>
        </inertial>
      </link>
      <joint name="right_joint" type="revolute">
        <parent>world</parent>
        <child>right</child>
        <axis>
          <xyz>0 0 1</xyz>
          <limit>
            <lower>0</lower>
            <upper>1.57</upper>
          </limit>
        </axis>
        <pose>0.3592100016664104 0 0 0 0 0</pose>
      </joint>
      <plugin name="register_component" filename="libregister_component.so">
        <component name="Door">
          <v_max_door>0.5</v_max_door>
          <a_max_door>0.3</a_max_door>
          <a_nom_door>0.15</a_nom_door>
          <dx_min_door>0.01</dx_min_door>
          <f_max_door>500.0</f_max_door>
          <ros_interface>true</ros_interface>
          <door name="door5" type="SwingDoor" left_joint_name="empty_joint" right_joint_name="right_joint" />
        </component>
      </plugin>
    </model>
    <include>
      <name>roomB_def_L2</name>
      <uri>model://roomB_def_L2</uri>
      <pose>0 0 8.0 0 0 0</pose>
    </include>
    <model name="ShaftDoor_lift_L1_doors">
      <pose>14.952096951797797 -29.533635883367598 0.0 0 0 1.5707</pose>
      <link name="right_door">
        <pose>0.25 0 1.25 0 0 0</pose>
        <visual name="right_door_visual">
          <geometry>
            <box>
              <size>0.5 0.03 2.5</size>
            </box>
          </geometry>
          <material>
            <ambient>0.5 0.5 0.5 1</ambient>
            <diffuse>0.7 0.7 0.7 1</diffuse>
            <specular>0.6 0.6 0.6 1</specular>
            <emissive>0.1 0.1 0.1 1</emissive>
          </material>
        </visual>
        <collision name="right_door_collision">
          <geometry>
            <box>
              <size>0.5 0.03 2.5</size>
            </box>
          </geometry>
          <surface>
            <contact>
              <collide_bitmask>0x02</collide_bitmask>
            </contact>
          </surface>
        </collision>
      </link>
      <link name="left_door">
        <pose>-0.25 0 1.25 0 0 0</pose>
        <visual name="left_door_visual">
          <geometry>
            <box>
              <size>0.5 0.03 2.5</size>
            </box>
          </geometry>
          <material>
            <ambient>0.5 0.5 0.5 1</ambient>
            <diffuse>0.7 0.7 0.7 1</diffuse>
            <specular>0.6 0.6 0.6 1</specular>
            <emissive>0.1 0.1 0.1 1</emissive>
          </material>
        </visual>
        <collision name="left_door_collision">
          <geometry>
            <box>
              <size>0.5 0.03 2.5</size>
            </box>
          </geometry>
          <surface>
            <contact>
              <collide_bitmask>0x02</collide_bitmask>
            </contact>
          </surface>
        </collision>
      </link>
      <joint name="right_joint" type="prismatic">
        <parent>world</parent>
        <child>right_door</child>
        <axis>
          <xyz>1 0 0</xyz>
          <limit>
            <lower>0</lower>
            <upper>0.5</upper>
          </limit>
        </axis>
      </joint>
      <joint name="left_joint" type="prismatic">
        <parent>world</parent>
        <child>left_door</child>
        <axis>
          <xyz>1 0 0</xyz>
          <limit>
            <lower>-0.5</lower>
            <upper>0</upper>
          </limit>
        </axis>
      </joint>
      <link name="ramp">
        <pose>0 0 -0.025 0 0 0</pose>
        <visual name="ramp_visual">
          <geometry>
            <box>
              <size>1.0 0.1 0.05</size>
            </box>
          </geometry>
          <material>
            <ambient>0.5 0.5 0.5 1</ambient>
            <diffuse>0.7 0.7 0.7 1</diffuse>
            <specular>0.6 0.6 0.6 1</specular>
            <emissive>0.1 0.1 0.1 1</emissive>
          </material>
        </visual>
        <collision name="ramp_collision">
          <geometry>
            <box>
              <size>1.0 0.1 0.05</size>
            </box>
          </geometry>
          <surface>
            <contact>
              <collide_bitmask>0x02</collide_bitmask>
            </contact>
          </surface>
        </collision>
      </link>
      <joint name="ramp_joint" type="fixed">
        <parent>world</parent>
        <child>ramp</child>
      </joint>
      <plugin name="register_component" filename="libregister_component.so">
        <component name="Door">
          <v_max_door>0.3</v_max_door>
          <a_max_door>0.2</a_max_door>
          <a_nom_door>0.1</a_nom_door>
          <dx_min_door>0.0001</dx_min_door>
          <f_max_door>35.0</f_max_door>
          <door left_joint_name="left_joint" name="ShaftDoor_lift_L1_doors" right_joint_name="right_joint" type="DoubleSlidingDoor" />
        </component>
      </plugin>
    </model>
    <model name="ShaftDoor_lift_L2_doors">
      <pose>14.952096951797797 -29.533635883367598 8.0 0 0 1.5707</pose>
      <link name="right_door">
        <pose>0.25 0 1.25 0 0 0</pose>
        <visual name="right_door_visual">
          <geometry>
            <box>
              <size>0.5 0.03 2.5</size>
            </box>
          </geometry>
          <material>
            <ambient>0.5 0.5 0.5 1</ambient>
            <diffuse>0.7 0.7 0.7 1</diffuse>
            <specular>0.6 0.6 0.6 1</specular>
            <emissive>0.1 0.1 0.1 1</emissive>
          </material>
        </visual>
        <collision name="right_door_collision">
          <geometry>
            <box>
              <size>0.5 0.03 2.5</size>
            </box>
          </geometry>
          <surface>
            <contact>
              <collide_bitmask>0x02</collide_bitmask>
            </contact>
          </surface>
        </collision>
      </link>
      <link name="left_door">
        <pose>-0.25 0 1.25 0 0 0</pose>
        <visual name="left_door_visual">
          <geometry>
            <box>
              <size>0.5 0.03 2.5</size>
            </box>
          </geometry>
          <material>
            <ambient>0.5 0.5 0.5 1</ambient>
            <diffuse>0.7 0.7 0.7 1</diffuse>
            <specular>0.6 0.6 0.6 1</specular>
            <emissive>0.1 0.1 0.1 1</emissive>
          </material>
        </visual>
        <collision name="left_door_collision">
          <geometry>
            <box>
              <size>0.5 0.03 2.5</size>
            </box>
          </geometry>
          <surface>
            <contact>
              <collide_bitmask>0x02</collide_bitmask>
            </contact>
          </surface>
        </collision>
      </link>
      <joint name="right_joint" type="prismatic">
        <parent>world</parent>
        <child>right_door</child>
        <axis>
          <xyz>1 0 0</xyz>
          <limit>
            <lower>0</lower>
            <upper>0.5</upper>
          </limit>
        </axis>
      </joint>
      <joint name="left_joint" type="prismatic">
        <parent>world</parent>
        <child>left_door</child>
        <axis>
          <xyz>1 0 0</xyz>
          <limit>
            <lower>-0.5</lower>
            <upper>0</upper>
          </limit>
        </axis>
      </joint>
      <link name="ramp">
        <pose>0 0 -0.025 0 0 0</pose>
        <visual name="ramp_visual">
          <geometry>
            <box>
              <size>1.0 0.1 0.05</size>
            </box>
          </geometry>
          <material>
            <ambient>0.5 0.5 0.5 1</ambient>
            <diffuse>0.7 0.7 0.7 1</diffuse>
            <specular>0.6 0.6 0.6 1</specular>
            <emissive>0.1 0.1 0.1 1</emissive>
          </material>
        </visual>
        <collision name="ramp_collision">
          <geometry>
            <box>
              <size>1.0 0.1 0.05</size>
            </box>
          </geometry>
          <surface>
            <contact>
              <collide_bitmask>0x02</collide_bitmask>
            </contact>
          </surface>
        </collision>
      </link>
      <joint name="ramp_joint" type="fixed">
        <parent>world</parent>
        <child>ramp</child>
      </joint>
      <plugin name="register_component" filename="libregister_component.so">
        <component name="Door">
          <v_max_door>0.3</v_max_door>
          <a_max_door>0.2</a_max_door>
          <a_nom_door>0.1</a_nom_door>
          <dx_min_door>0.0001</dx_min_door>
          <f_max_door>35.0</f_max_door>
          <door left_joint_name="left_joint" name="ShaftDoor_lift_L2_doors" right_joint_name="right_joint" type="DoubleSlidingDoor" />
        </component>
      </plugin>
    </model>
    <model name="lift">
      <link name="platform">
        <inertial>
          <mass>1200</mass>
          <inertia>
            <ixx>361.25</ixx>
            <iyy>324.25</iyy>
            <izz>685.0</izz>
          </inertia>
        </inertial>
        <visual name="floor_visual">
          <pose>0 0 -0.025 0 0 0</pose>
          <geometry>
            <box>
              <size>1.9 1.8 0.05</size>
            </box>
          </geometry>
          <material>
            <ambient>0.5 0.5 0.5 1</ambient>
            <diffuse>0.7 0.7 0.7 1</diffuse>
            <specular>0.6 0.6 0.6 1</specular>
            <emissive>0.1 0.1 0.1 1</emissive>
          </material>
        </visual>
        <collision name="floor_collision">
          <pose>0 0 -0.025 0 0 0</pose>
          <geometry>
            <box>
              <size>1.9 1.8 0.05</size>
            </box>
          </geometry>
          <surface>
            <contact>
              <collide_bitmask>0x01</collide_bitmask>
            </contact>
          </surface>
        </collision>
        <visual name="frontwall1_visual">
          <pose>0.0 0.875 1.25 0 0 0</pose>
          <geometry>
            <box>
              <size>1.9 0.05 2.5</size>
            </box>
          </geometry>
          <material>
            <ambient>0.5 0.5 0.5 1</ambient>
            <diffuse>0.7 0.7 0.7 1</diffuse>
            <specular>0.6 0.6 0.6 1</specular>
            <emissive>0.1 0.1 0.1 1</emissive>
          </material>
        </visual>
        <collision name="frontwall1_collision">
          <pose>0.0 0.875 1.25 0 0 0</pose>
          <geometry>
            <box>
              <size>1.9 0.05 2.5</size>
            </box>
          </geometry>
          <surface>
            <contact>
              <collide_bitmask>0x01</collide_bitmask>
            </contact>
          </surface>
        </collision>
        <visual name="backwall1_visual">
          <pose>0.0 -0.875 1.25 0 0 0</pose>
          <geometry>
            <box>
              <size>1.9 0.05 2.5</size>
            </box>
          </geometry>
          <material>
            <ambient>0.5 0.5 0.5 1</ambient>
            <diffuse>0.7 0.7 0.7 1</diffuse>
            <specular>0.6 0.6 0.6 1</specular>
            <emissive>0.1 0.1 0.1 1</emissive>
          </material>
        </visual>
        <collision name="backwall1_collision">
          <pose>0.0 -0.875 1.25 0 0 0</pose>
          <geometry>
            <box>
              <size>1.9 0.05 2.5</size>
            </box>
          </geometry>
          <surface>
            <contact>
              <collide_bitmask>0x01</collide_bitmask>
            </contact>
          </surface>
        </collision>
        <visual name="leftwall1_visual">
          <pose>-0.9249999999999999 0.0 1.25 0 0 1.5707963267948966</pose>
          <geometry>
            <box>
              <size>1.7 0.05 2.5</size>
            </box>
          </geometry>
          <material>
            <ambient>0.5 0.5 0.5 1</ambient>
            <diffuse>0.7 0.7 0.7 1</diffuse>
            <specular>0.6 0.6 0.6 1</specular>
            <emissive>0.1 0.1 0.1 1</emissive>
          </material>
        </visual>
        <collision name="leftwall1_collision">
          <pose>-0.9249999999999999 0.0 1.25 0 0 1.5707963267948966</pose>
          <geometry>
            <box>
              <size>1.7 0.05 2.5</size>
            </box>
          </geometry>
          <surface>
            <contact>
              <collide_bitmask>0x01</collide_bitmask>
            </contact>
          </surface>
        </collision>
        <visual name="rightwall1_visual">
          <pose>0.9249999999999999 -0.675 1.25 0 0 1.5707963267948966</pose>
          <geometry>
            <box>
              <size>0.35 0.05 2.5</size>
            </box>
          </geometry>
          <material>
            <ambient>0.5 0.5 0.5 1</ambient>
            <diffuse>0.7 0.7 0.7 1</diffuse>
            <specular>0.6 0.6 0.6 1</specular>
            <emissive>0.1 0.1 0.1 1</emissive>
          </material>
        </visual>
        <collision name="rightwall1_collision">
          <pose>0.9249999999999999 -0.675 1.25 0 0 1.5707963267948966</pose>
          <geometry>
            <box>
              <size>0.35 0.05 2.5</size>
            </box>
          </geometry>
          <surface>
            <contact>
              <collide_bitmask>0x01</collide_bitmask>
            </contact>
          </surface>
        </collision>
        <visual name="rightwall2_visual">
          <pose>0.9249999999999999 0.675 1.25 0 0 1.5707963267948966</pose>
          <geometry>
            <box>
              <size>0.35 0.05 2.5</size>
            </box>
          </geometry>
          <material>
            <ambient>0.5 0.5 0.5 1</ambient>
            <diffuse>0.7 0.7 0.7 1</diffuse>
            <specular>0.6 0.6 0.6 1</specular>
            <emissive>0.1 0.1 0.1 1</emissive>
          </material>
        </visual>
        <collision name="rightwall2_collision">
          <pose>0.9249999999999999 0.675 1.25 0 0 1.5707963267948966</pose>
          <geometry>
            <box>
              <size>0.35 0.05 2.5</size>
            </box>
          </geometry>
          <surface>
            <contact>
              <collide_bitmask>0x01</collide_bitmask>
            </contact>
          </surface>
        </collision>
      </link>
      <joint name="cabin_joint" type="prismatic">
        <parent>world</parent>
        <child>platform</child>
        <axis>
          <xyz>0 0 1</xyz>
        </axis>
      </joint>
      <model name="CabinDoor_lift_doors">
        <pose>0.9249999999999999 0.0 0 0 0 1.5707</pose>
        <link name="right_door">
          <pose>0.25 0 1.25 0 0 0</pose>
          <visual name="right_door_visual">
            <geometry>
              <box>
                <size>0.5 0.03 2.5</size>
              </box>
            </geometry>
            <material>
              <ambient>0.5 0.5 0.5 1</ambient>
              <diffuse>0.7 0.7 0.7 1</diffuse>
              <specular>0.6 0.6 0.6 1</specular>
              <emissive>0.1 0.1 0.1 1</emissive>
            </material>
          </visual>
          <collision name="right_door_collision">
            <geometry>
              <box>
                <size>0.5 0.03 2.5</size>
              </box>
            </geometry>
            <surface>
              <contact>
                <collide_bitmask>0x02</collide_bitmask>
              </contact>
            </surface>
          </collision>
        </link>
        <link name="left_door">
          <pose>-0.25 0 1.25 0 0 0</pose>
          <visual name="left_door_visual">
            <geometry>
              <box>
                <size>0.5 0.03 2.5</size>
              </box>
            </geometry>
            <material>
              <ambient>0.5 0.5 0.5 1</ambient>
              <diffuse>0.7 0.7 0.7 1</diffuse>
              <specular>0.6 0.6 0.6 1</specular>
              <emissive>0.1 0.1 0.1 1</emissive>
            </material>
          </visual>
          <collision name="left_door_collision">
            <geometry>
              <box>
                <size>0.5 0.03 2.5</size>
              </box>
            </geometry>
            <surface>
              <contact>
                <collide_bitmask>0x02</collide_bitmask>
              </contact>
            </surface>
          </collision>
        </link>
        <plugin name="register_component" filename="libregister_component.so">
          <component name="Door">
            <v_max_door>0.3</v_max_door>
            <a_max_door>0.2</a_max_door>
            <a_nom_door>0.1</a_nom_door>
            <dx_min_door>0.0001</dx_min_door>
            <f_max_door>35.0</f_max_door>
            <door left_joint_name="CabinDoor_lift_doors_left_joint" name="CabinDoor_lift_doors" right_joint_name="CabinDoor_lift_doors_right_joint" type="DoubleSlidingDoor" />
          </component>
        </plugin>
      </model>
      <joint name="CabinDoor_lift_doors_right_joint" type="prismatic">
        <parent>platform</parent>
        <child>CabinDoor_lift_doors::right_door</child>
        <axis>
          <xyz>1 0 0</xyz>
          <limit>
            <lower>0</lower>
            <upper>0.5</upper>
          </limit>
        </axis>
      </joint>
      <joint name="CabinDoor_lift_doors_left_joint" type="prismatic">
        <parent>platform</parent>
        <child>CabinDoor_lift_doors::left_door</child>
        <axis>
          <xyz>1 0 0</xyz>
          <limit>
            <lower>-0.5</lower>
            <upper>0</upper>
          </limit>
        </axis>
      </joint>
      <plugin name="register_component" filename="libregister_component.so">
        <component name="Lift">
          <lift_name>lift</lift_name>
          <floor name="L1" elevation="0.0">
            <door_pair cabin_door="CabinDoor_lift_doors" shaft_door="ShaftDoor_lift_L1_doors" />
          </floor>
          <floor name="L2" elevation="8.0">
            <door_pair cabin_door="CabinDoor_lift_doors" shaft_door="ShaftDoor_lift_L2_doors" />
          </floor>
          <initial_floor>L1</initial_floor>
          <v_max_cabin>2.0</v_max_cabin>
          <a_max_cabin>1.2</a_max_cabin>
          <a_nom_cabin>1.0</a_nom_cabin>
          <dx_min_cabin>0.001</dx_min_cabin>
          <f_max_cabin>25323.0</f_max_cabin>
          <cabin_joint_name>cabin_joint</cabin_joint_name>
        </component>
      </plugin>
      <pose>13.952096951797797 -29.533635883367598 0 0 0 0.0</pose>
    </model>
    <rmf_charger_waypoints name="charger_waypoints">
      <rmf_vertex name="tinyRobot1_charger" x="14.026694842434232" y="-10.407347764927534" level="L1" />
    </rmf_charger_waypoints>
  </world>
</sdf>
